<!--
	File autogenerated from OnShape exporter.
	Timestamp: 2022-06-20-14:55:21
	Exporter Git Commit Hash: a278511934049e6f8f56b7acad89d937a79011d1
	OnShape Microversion ID: 65d6e7af157a21df5c5a79c3
	robots/lsa_1.1_full/config.yml:
	{
		documentId: 0fd9bb9a29bd34da8f37550f
		workspaceId: 00709c39a3c048f1bddaec31
		assemblyName: LSA V1.1
		robotName: LSA
		jointLimits: joint_limits.yml
		massProps: mass_props.yml
		configuration: 		{
			Configuration: Neutral
			Passive Markers: False
			Apriltags: False
		}
		decimate: True
		generateCollisionHullURDF: True
	}
-->
<!--
	File updated by OnShape exporter script: scripts/process_joint_limits.py
	Timestamp: 2022-06-20-15:14:27
	Config File: robots/lsa_1.1_full/joint_limits.yml
	Script Commit Hash: a278511934049e6f8f56b7acad89d937a79011d1
-->
<!--
	File updated by OnShape exporter script: scripts/process_mass_properties.py
	Timestamp: 2022-06-20-15:14:27
	Config File: robots/lsa_1.1_full/mass_props.yml
	Script Commit Hash: a278511934049e6f8f56b7acad89d937a79011d1
-->
<!--
	File updated by OnShape exporter script: scripts/generate_hulls.py
	Timestamp: 2022-06-20-15:21:59
	Script Commit Hash: a278511934049e6f8f56b7acad89d937a79011d1
-->
<robot name="LSA">

<link name="world" />

<joint name="world_to_base" type="fixed">
<parent link="world" />
<child link="root_link" />
<origin rpy="0 0 0" xyz="0 0 0" />
</joint>

<link name="root_link">
<visual>
<origin xyz="9.47873756175138e-18 -2.856872724499304e-17 -0.024000000000000684" rpy="-2.7618585142051945e-16 -0.0 6.8534929388594916e-31" />
<geometry>
<mesh filename="./lsa1.1_new//meshes/urdf/obj_combined_hulls/root_link.obj" />
</geometry>
</visual>
<collision>
<origin xyz="9.47873756175138e-18 -2.856872724499304e-17 -0.024000000000000684" rpy="-2.7618585142051945e-16 -0.0 6.8534929388594916e-31" />
<geometry>
<mesh filename="./lsa1.1_new//meshes/urdf/obj_combined_hulls/root_link.obj" />
</geometry>
</collision>
<inertial>
<origin xyz="0.00679928302344931 6.653692674201541e-07 -0.27815003570157115" rpy="0 0 0" />
<mass value="7.183594348600132" />
<inertia ixx="0.31483080293207405" ixy="5.062017097616084e-07" ixz="0.021323894598139104" iyy="0.3143282448173946" iyz="-1.2779834144653864e-06" izz="0.032395636611825186" />
</inertial>
</link>

<link name="torso_waist_tracker_link" />

<joint name="torso_waist_tracker" type="fixed">
<origin xyz="-1.0600000000000405 -2.849952389034642e-16 1.0380000000000296" rpy="1.5707963267948966 -2.76185851420519e-16 -1.5707963267948983" />
<parent link="root_link" />
<child link="torso_waist_tracker_link" />
</joint>

<link name="wheel_base_link" />

<joint name="wheel_base" type="fixed">
<origin xyz="6.666762321308809e-11 -2.856872724268543e-17 -1.0627921111110301" rpy="-2.7618585142051945e-16 6.123233995736713e-17 6.853492938860852e-31" />
<parent link="root_link" />
<child link="wheel_base_link" />
</joint>

<link name="speaker_link" />

<joint name="speaker" type="fixed">
<origin xyz="0.06817500000000258 -2.0649219571397805e-15 -0.5667000000000009" rpy="1.5707963267948957 2.761858514205178e-16 1.5707963267948946" />
<parent link="root_link" />
<child link="speaker_link" />
</joint>

<link name="torso_yaw_link">
<visual>
<origin xyz="0.0 1.262177448353619e-29 4.3368086899380734e-19" rpy="-1.8325957145940461 1.5707963267948966 0.0" />
<geometry>
<mesh filename="./lsa1.1_new//meshes/urdf/obj_combined_hulls/torso_yaw_link.obj" />
</geometry>
</visual>
<collision>
<origin xyz="0.0 1.262177448353619e-29 4.3368086899380734e-19" rpy="-1.8325957145940461 1.5707963267948966 0.0" />
<geometry>
<mesh filename="./lsa1.1_new//meshes/urdf/obj_combined_hulls/torso_yaw_link.obj" />
</geometry>
</collision>
<inertial>
<origin xyz="-0.00166403 -0.0101463 0.0623078" rpy="0 0 0" />
<mass value="1.922" />
<inertia ixx="0.006378107099964676" ixy="6.59823948125347e-05" ixz="4.522349518090528e-05" iyy="0.00268619309683605" iyz="0.0003399816945047182" izz="0.005342834122218298" />
</inertial>
</link>

<joint name="torso_yaw" type="revolute">
<origin xyz="-3.1105803444498797e-15 -5.762979069651171e-14 3.187988067975982e-15" rpy="3.7495554139391605e-14 2.213579307108516e-14 -1.4624371897651312e-14" />
<parent link="root_link" />
<child link="torso_yaw_link" />
<axis xyz="2.2135793071084816e-14 -3.77717399908133e-14 1.0000000000000007" />
<limit effort="70.0" velocity="4.1" lower="-0.7853981633974483" upper="0.7853981633974483" />

</joint>

<link name="torso_pitch_lower_motor_link" />

<joint name="torso_pitch_lower_motor" type="fixed">
<origin xyz="-4.144403142988938e-16 0.015999999999999945 0.05599999999999992" rpy="-1.5707963267949012 1.7267553484046907e-16 -4.685887851807436e-14" />
<parent link="torso_yaw_link" />
<child link="torso_pitch_lower_motor_link" />
</joint>

<link name="torso_yaw_motor_link" />

<joint name="torso_yaw_motor" type="fixed">
<origin xyz="-4.027258048777949e-16 0.016249999999999945 0.05599999999999992" rpy="-1.5707963267949012 1.7267553484046907e-16 -4.685887851807436e-14" />
<parent link="torso_yaw_link" />
<child link="torso_yaw_motor_link" />
</joint>

<link name="torso_yaw_right_bearing_link" />

<joint name="torso_yaw_right_bearing" type="fixed">
<origin xyz="-3.832280011987365e-15 -0.08550037499999534 0.056000000000000494" rpy="-1.5707963267948972 3.9027887911559104e-16 1.456074087236189e-14" />
<parent link="torso_yaw_link" />
<child link="torso_yaw_right_bearing_link" />
</joint>

<link name="torso_yaw_left_bearing_link" />

<joint name="torso_yaw_left_bearing" type="fixed">
<origin xyz="2.9865244537367953e-15 0.08549999999999532 0.05599999999999969" rpy="-1.5707963267948972 3.9027887911559104e-16 1.456074087236189e-14" />
<parent link="torso_yaw_link" />
<child link="torso_yaw_left_bearing_link" />
</joint>

<link name="column_link">
<visual>
<origin xyz="-0.5360921073749237 0.05350000000033585 -0.11149999999987684" rpy="-3.141592653589793 -1.570796326794666 0.0" />
<geometry>
<mesh filename="./lsa1.1_new//meshes/urdf/obj_combined_hulls/column_link.obj" />
</geometry>
</visual>
<collision>
<origin xyz="-0.5360921073749237 0.05350000000033585 -0.11149999999987684" rpy="-3.141592653589793 -1.570796326794666 0.0" />
<geometry>
<mesh filename="./lsa1.1_new//meshes/urdf/obj_combined_hulls/column_link.obj" />
</geometry>
</collision>
<inertial>
<origin xyz="-0.2587693741131646 -0.17621985650592253 -0.11419698569756352" rpy="0 0 0" />
<mass value="48.304328694909294" />
<inertia ixx="1.9653289493747241" ixy="-0.001015432598232359" ixz="0.01099672538418078" iyy="1.1643347774970843" iyz="0.017423051358169128" izz="2.1992079257141928" />
</inertial>
</link>

<joint name="column" type="fixed">
<origin xyz="-0.047499999999995386 0.11149999999998736 -0.44170000000000265" rpy="-1.5707963267948974 -1.5707963267948728 0.0" />
<parent link="root_link" />
<child link="column_link" />
<axis xyz="3.1554436208840472e-30 8.332029653868598e-30 1.0" />
</joint>

<link name="torso_pitch_lower_link">
<visual>
<origin xyz="0.08 0.0 -0.08549999999999999" rpy="-1.5707963267948966 5.328688394996611e-30 1.5707963267948966" />
<geometry>
<mesh filename="./lsa1.1_new//meshes/urdf/obj_combined_hulls/torso_pitch_lower_link.obj" />
</geometry>
</visual>
<collision>
<origin xyz="0.08 0.0 -0.08549999999999999" rpy="-1.5707963267948966 5.328688394996611e-30 1.5707963267948966" />
<geometry>
<mesh filename="./lsa1.1_new//meshes/urdf/obj_combined_hulls/torso_pitch_lower_link.obj" />
</geometry>
</collision>
<inertial>
<origin xyz="-0.07573732954220565 -0.012714319395604561 -0.07998181952541111" rpy="0 0 0" />
<mass value="0.5423763129502652" />
<inertia ixx="0.0035963261683322626" ixy="-0.00025112304608164296" ixz="1.1650452549459382e-05" iyy="0.004013441490397242" iyz="5.2337508120182574e-06" izz="0.0017308649418825922" />
</inertial>
</link>

<joint name="torso_pitch_lower" type="revolute">
<origin xyz="-3.8322800119873655e-15 -0.08550037499999534 0.05599999999998974" rpy="1.5707963267948197 1.5707963267948657 0.0" />
<parent link="torso_yaw_link" />
<child link="torso_pitch_lower_link" />
<axis xyz="-3.059755751267585e-14 6.233280923648332e-14 1.0000000000000073" />
<limit effort="70.0" velocity="4.1" lower="-0.5235987755982988" upper="0.2617993877991494" />

</joint>

<link name="hydraulic_container_link">
<visual>
<origin xyz="1.3877787807814457e-17 0.0 -0.01905000000000001" rpy="1.5707963267948966 -0.0 -3.95206709005231e-32" />
<geometry>
<mesh filename="./lsa1.1_new//meshes/urdf/obj_combined_hulls/hydraulic_container_link.obj" />
</geometry>
</visual>
<collision>
<origin xyz="1.3877787807814457e-17 0.0 -0.01905000000000001" rpy="1.5707963267948966 -0.0 -3.95206709005231e-32" />
<geometry>
<mesh filename="./lsa1.1_new//meshes/urdf/obj_combined_hulls/hydraulic_container_link.obj" />
</geometry>
</collision>
<inertial>
<origin xyz="-0.08834957841548317 -0.10673214342752788 -0.3161666728897021" rpy="0 0 0" />
<mass value="10.705259239944729" />
<inertia ixx="0.36794648450690826" ixy="0.0001526706629178361" ixz="3.670399565378849e-05" iyy="0.3684954243891234" iyz="0.00943033596260982" izz="0.15560447886058354" />
</inertial>
</link>

<joint name="hydraulic_container" type="fixed">
<origin xyz="0.009699999999980224 -0.16850000000003526 -0.023131999999876862" rpy="-1.2082366638804501e-13 -1.5707963267948966 0.0" />
<parent link="column_link" />
<child link="hydraulic_container_link" />
<axis xyz="0.0 7.573064690121713e-29 1.0" />
</joint>

<link name="left_wheel_link">
<visual>
<origin xyz="1.3877787807814457e-15 0.13999999999999058 0.17820069103793562" rpy="1.5707963267948966 1.5707963267948966 0.0" />
<geometry>
<mesh filename="./lsa1.1_new//meshes/urdf/obj_combined_hulls/left_wheel_link.obj" />
</geometry>
</visual>
<collision>
<origin xyz="1.3877787807814457e-15 0.13999999999999058 0.17820069103793562" rpy="1.5707963267948966 1.5707963267948966 0.0" />
<geometry>
<mesh filename="./lsa1.1_new//meshes/urdf/obj_combined_hulls/left_wheel_link.obj" />
</geometry>
</collision>
<inertial>
<origin xyz="9.333270776421728e-06 1.283040296112814e-05 -0.027637123710610084" rpy="0 0 0" />
<mass value="1.049343517474219" />
<inertia ixx="0.007013006404082125" ixy="1.53464755472883e-07" ixz="1.3339394225848444e-08" iyy="0.007013229323611871" iyz="-4.168210127299714e-07" izz="0.012711747618871604" />
</inertial>
</link>

<joint name="left_wheel" type="continuous">
<origin xyz="-0.48119999999998797 0.048500000000026085 0.06670100000014316" rpy="-3.141592653589793 -3.4943327596080453e-17 -1.5707963267950282" />
<parent link="column_link" />
<child link="left_wheel_link" />
<axis xyz="3.4943327596057416e-17 -1.868022623563356e-27 1.0" />
<limit effort="30" velocity="7.14" />

</joint>

<link name="right_wheel_link">
<visual>
<origin xyz="-6.659169743405968e-16 -0.13999999999999047 0.17820069103793554" rpy="-1.5707963267948966 -1.5707963267948966 0.0" />
<geometry>
<mesh filename="./lsa1.1_new//meshes/urdf/obj_combined_hulls/right_wheel_link.obj" />
</geometry>
</visual>
<collision>
<origin xyz="-6.659169743405968e-16 -0.13999999999999047 0.17820069103793554" rpy="-1.5707963267948966 -1.5707963267948966 0.0" />
<geometry>
<mesh filename="./lsa1.1_new//meshes/urdf/obj_combined_hulls/right_wheel_link.obj" />
</geometry>
</collision>
<inertial>
<origin xyz="-9.333277032410194e-06 -1.2830387295881263e-05 -0.02763712371060159" rpy="0 0 0" />
<mass value="1.049343517474864" />
<inertia ixx="0.00701300640407758" ixy="1.5346481107314241e-07" ixz="-1.3339239467798026e-08" iyy="0.007013229323633407" iyz="4.168206251659545e-07" izz="0.012711747618888656" />
</inertial>
</link>

<joint name="right_wheel" type="continuous">
<origin xyz="-0.4811999999999881 0.048500000000026085 -0.2897009999998568" rpy="1.9216651651183848e-27 -3.4943327596080453e-17 -1.5707963267950282" />
<parent link="column_link" />
<child link="right_wheel_link" />
<axis xyz="-3.4943327596057416e-17 -1.868022623563356e-27 1.0" />
<limit effort="30" velocity="7.14" />

</joint>

<link name="left_caster_swivel_link">
<visual>
<origin xyz="-0.13224999876448648 -0.4734999999999997 -0.18342210737489983" rpy="0.0 -5.543281940506e-09 3.1309853526513357e-32" />
<geometry>
<mesh filename="./lsa1.1_new//meshes/urdf/obj_combined_hulls/left_caster_swivel_link.obj" />
</geometry>
</visual>
<collision>
<origin xyz="-0.13224999876448648 -0.4734999999999997 -0.18342210737489983" rpy="0.0 -5.543281940506e-09 3.1309853526513357e-32" />
<geometry>
<mesh filename="./lsa1.1_new//meshes/urdf/obj_combined_hulls/left_caster_swivel_link.obj" />
</geometry>
</collision>
<inertial>
<origin xyz="-1.5553471270473349e-06 0.03560815387965185 -0.09170981512775853" rpy="0 0 0" />
<mass value="0.5011401476986359" />
<inertia ixx="0.0016012393673076105" ixy="1.5757387114749748e-08" ixz="-1.5056085251611842e-08" iyy="0.0010928191052211292" iyz="0.0001539468728223525" izz="0.0006866383213370814" />
</inertial>
</link>

<joint name="left_caster_swivel" type="continuous">
<origin xyz="-0.4376700007331501 -0.42599999999997934 0.020749999781370113" rpy="3.1415926535896617 -1.5707963212516147 0.0" />
<parent link="column_link" />
<child link="left_caster_swivel_link" />
<axis xyz="0.0 -1.9573847869067922e-25 1.0" />
<limit effort="0" velocity="0" />

</joint>

<link name="right_caster_swivel_link">
<visual>
<origin xyz="0.13225000123551348 -0.4734999999999997 -0.18342210737489995" rpy="0.0 -5.543281940506e-09 3.1309853526513357e-32" />
<geometry>
<mesh filename="./lsa1.1_new//meshes/urdf/obj_combined_hulls/right_caster_swivel_link.obj" />
</geometry>
</visual>
<collision>
<origin xyz="0.13225000123551348 -0.4734999999999997 -0.18342210737489995" rpy="0.0 -5.543281940506e-09 3.1309853526513357e-32" />
<geometry>
<mesh filename="./lsa1.1_new//meshes/urdf/obj_combined_hulls/right_caster_swivel_link.obj" />
</geometry>
</collision>
<inertial>
<origin xyz="-1.5553483571841523e-06 0.03560815387962095 -0.09170981512118676" rpy="0 0 0" />
<mass value="0.501140147758996" />
<inertia ixx="0.0016012393675204936" ixy="1.5757386469422163e-08" ixz="-1.505603476014013e-08" iyy="0.0010928191054480783" iyz="0.00015394687282121674" izz="0.0006866383213519762" />
</inertial>
</link>

<joint name="right_caster_swivel" type="continuous">
<origin xyz="-0.4376699992669518 -0.42599999999997934 -0.24375000021862986" rpy="3.1415926535896617 -1.5707963212516147 0.0" />
<parent link="column_link" />
<child link="right_caster_swivel_link" />
<axis xyz="0.0 -1.9573847869067922e-25 1.0" />
<limit effort="0" velocity="0" />

</joint>

<link name="torso_pitch_upper_link">
<visual>
<origin xyz="0.0 2.7755575615628914e-17 0.003500000000000003" rpy="-1.5519979019635813e-30 1.5707963267948966 0.0" />
<geometry>
<mesh filename="./lsa1.1_new//meshes/urdf/obj_combined_hulls/torso_pitch_upper_link.obj" />
</geometry>
</visual>
<collision>
<origin xyz="0.0 2.7755575615628914e-17 0.003500000000000003" rpy="-1.5519979019635813e-30 1.5707963267948966 0.0" />
<geometry>
<mesh filename="./lsa1.1_new//meshes/urdf/obj_combined_hulls/torso_pitch_upper_link.obj" />
</geometry>
</collision>
<inertial>
<origin xyz="-0.015243445582268634 -0.14733934317604153 0.07604282037510816" rpy="0 0 0" />
<mass value="5.391439784540943" />
<inertia ixx="0.08453956115277658" ixy="-0.004628728157891779" ixz="0.0007906091526285789" iyy="0.028338851252210997" iyz="0.006181040264228648" izz="0.06417020298910171" />
</inertial>
</link>

<joint name="torso_pitch_upper" type="continuous">
<origin xyz="-0.09272887864750137 -0.02484663665963369 9.575673587391975e-16" rpy="-3.141592653589763 2.1637508065301426e-17 1.5707963267948966" />
<parent link="torso_pitch_lower_link" />
<child link="torso_pitch_upper_link" />
<axis xyz="-1.8748044307837196e-17 -3.013566795201047e-14 0.9999999999999998" />
<mimic joint="torso_pitch_lower" multiplier="-1.0" offset="0" />
<limit effort="70.0" velocity="4.1" />

</joint>

<link name="torso_pitch_right_bearing_link" />

<joint name="torso_pitch_right_bearing" type="fixed">
<origin xyz="1.742176880649995e-32 2.7755575615628907e-17 3.469446951953614e-18" rpy="-1.896441462393579e-30 -1.776556724364418e-30 1.5519979019635813e-30" />
<parent link="torso_pitch_upper_link" />
<child link="torso_pitch_right_bearing_link" />
</joint>

<link name="left_chest_motor_link" />

<joint name="left_chest_motor" type="fixed">
<origin xyz="-0.025653371670167333 -0.19995862067625816 0.15835619374420207" rpy="2.6179938779915037 -5.329070518200505e-15 3.1415926535897563" />
<parent link="torso_pitch_upper_link" />
<child link="left_chest_motor_link" />
</joint>

<link name="torso_pitch_upper_motor_link" />

<joint name="torso_pitch_upper_motor" type="fixed">
<origin xyz="-8.329845799237567e-09 6.762583826258606e-10 0.10175000000000357" rpy="-1.7569404246260578e-14 3.581844210917116e-14 -3.578656032529209e-14" />
<parent link="torso_pitch_upper_link" />
<child link="torso_pitch_upper_motor_link" />
</joint>

<link name="torso_pitch_left_bearing_link" />

<joint name="torso_pitch_left_bearing" type="fixed">
<origin xyz="-1.5161483180037296e-15 2.239652907576328e-15 0.17100000000000687" rpy="-2.4424906541753527e-15 2.6378890550100975e-30 -2.220446049250297e-16" />
<parent link="torso_pitch_upper_link" />
<child link="torso_pitch_left_bearing_link" />
</joint>

<link name="torso_chest_tracker_link" />

<joint name="torso_chest_tracker" type="fixed">
<origin xyz="0.028346619999989633 -0.16819490725265443 0.0855000000000055" rpy="-3.141592653589757 1.5707963267948568 0.0" />
<parent link="torso_pitch_upper_link" />
<child link="torso_chest_tracker_link" />
</joint>

<link name="left_caster_link">
<visual>
<origin xyz="-0.07630210737489995 -0.5134999999999996 0.13224999876448534" rpy="-0.0 1.5707963212516147 0.0" />
<geometry>
<mesh filename="./lsa1.1_new//meshes/urdf/obj_combined_hulls/left_caster_link.obj" />
</geometry>
</visual>
<collision>
<origin xyz="-0.07630210737489995 -0.5134999999999996 0.13224999876448534" rpy="-0.0 1.5707963212516147 0.0" />
<geometry>
<mesh filename="./lsa1.1_new//meshes/urdf/obj_combined_hulls/left_caster_link.obj" />
</geometry>
</collision>
<inertial>
<origin xyz="-1.2572706368507713e-06 4.0777852664541925e-06 8.99217845462541e-08" rpy="0 0 0" />
<mass value="0.5220211600449411" />
<inertia ixx="0.0008313444910895271" ixy="-2.0089968601291447e-08" ixz="-4.445201906547108e-08" iyy="0.0008313967711645181" iyz="-3.672457956702592e-08" izz="0.0016077080244882112" />
</inertial>
</link>

<joint name="left_caster" type="continuous">
<origin xyz="-1.1102230246251565e-15 0.03999999999999987 -0.10711999999999988" rpy="2.1811774521457205e-32 -1.5707963267948966 0.0" />
<parent link="left_caster_swivel_link" />
<child link="left_caster_link" />
<axis xyz="0.0 -2.1811774521457205e-32 1.0" />
<limit effort="0" velocity="0" />

</joint>

<link name="right_caster_link">
<visual>
<origin xyz="-0.07630210737489995 0.5134999999999996 0.13225000123551353" rpy="-3.141592653589793 -1.5707963212516147 0.0" />
<geometry>
<mesh filename="./lsa1.1_new//meshes/urdf/obj_combined_hulls/right_caster_link.obj" />
</geometry>
</visual>
<collision>
<origin xyz="-0.07630210737489995 0.5134999999999996 0.13225000123551353" rpy="-3.141592653589793 -1.5707963212516147 0.0" />
<geometry>
<mesh filename="./lsa1.1_new//meshes/urdf/obj_combined_hulls/right_caster_link.obj" />
</geometry>
</collision>
<inertial>
<origin xyz="4.07778526634317e-06 1.2572706368230158e-06 8.992178457400968e-08" rpy="0 0 0" />
<mass value="0.5220211600449416" />
<inertia ixx="0.0008313967711645197" ixy="2.0089968601375638e-08" ixz="-3.672457956699712e-08" iyy="0.0008313444910895283" iyz="4.4452019065448346e-08" izz="0.0016077080244882112" />
</inertial>
</link>

<joint name="right_caster" type="continuous">
<origin xyz="-5.551115123125783e-17 0.03999999999999987 -0.10711999999999999" rpy="-3.141592653589793 -1.5707963267948966 0.0" />
<parent link="right_caster_swivel_link" />
<child link="right_caster_link" />
<axis xyz="0.0 -2.1811774521457205e-32 1.0" />
<limit effort="0" velocity="0" />

</joint>

<link name="right_shoulder_fe_link">
<visual>
<origin xyz="-6.938893903907228e-18 0.0 0.06937500000000008" rpy="-5.586166405652295e-31 1.0471975511965979 1.5707963267948966" />
<geometry>
<mesh filename="./lsa1.1_new//meshes/urdf/obj_combined_hulls/right_shoulder_fe_link.obj" />
</geometry>
</visual>
<collision>
<origin xyz="-6.938893903907228e-18 0.0 0.06937500000000008" rpy="-5.586166405652295e-31 1.0471975511965979 1.5707963267948966" />
<geometry>
<mesh filename="./lsa1.1_new//meshes/urdf/obj_combined_hulls/right_shoulder_fe_link.obj" />
</geometry>
</collision>
<inertial>
<origin xyz="0.01804580832985173 0.02121518988650123 0.07186595457686923" rpy="0 0 0" />
<mass value="0.96" />
<inertia ixx="0.0011118011274775616" ixy="1.3330532192125175e-05" ixz="-0.00015374811936521172" iyy="0.0015260836322637708" iyz="-3.75399226410233e-06" izz="0.0012180806877555345" />
</inertial>
</link>

<joint name="right_shoulder_fe" type="revolute">
<origin xyz="-0.025653371670199543 -0.21558362067625494 -0.014419487612456233" rpy="2.6179938779914598 5.94530700557959e-14 -2.825363035797169e-14" />
<parent link="torso_pitch_upper_link" />
<child link="right_shoulder_fe_link" />
<axis xyz="1.8306063673256304e-15 5.398712404411842e-15 0.9999999999999682" />
<limit effort="36" velocity="8.9" lower="-0.7853981633974483" upper="3.141592653589793" />

</joint>

<link name="neck_yaw_link">
<visual>
<origin xyz="6.1235188130565575e-19 0.0 0.0" rpy="-1.964072326306217e-30 -1.0275302189876902e-17 1.5707963267948966" />
<geometry>
<mesh filename="./lsa1.1_new//meshes/urdf/obj_combined_hulls/neck_yaw_link.obj" />
</geometry>
</visual>
<collision>
<origin xyz="6.1235188130565575e-19 0.0 0.0" rpy="-1.964072326306217e-30 -1.0275302189876902e-17 1.5707963267948966" />
<geometry>
<mesh filename="./lsa1.1_new//meshes/urdf/obj_combined_hulls/neck_yaw_link.obj" />
</geometry>
</collision>
<inertial>
<origin xyz="-4.899550065642449e-06 -0.011644661517631646 0.04616318477068648" rpy="0 0 0" />
<mass value="0.122" />
<inertia ixx="0.000102013271703066" ixy="-1.4630705843483473e-07" ixz="-6.556765654852104e-09" iyy="0.00011048127954380077" iyz="2.5412351849033873e-05" izz="0.00015080123327545795" />
</inertial>
</link>

<joint name="neck_yaw" type="revolute">
<origin xyz="-0.011122904334320713 -0.272519257214183 0.08550000000007436" rpy="1.692969374434425 -1.5707963267948821 0.0" />
<parent link="torso_pitch_upper_link" />
<child link="neck_yaw_link" />
<axis xyz="-2.2848118499191356e-18 3.450421829567995e-14 0.9999999999999939" />
<limit effort="19" velocity="8.9" lower="-1.5707963267948966" upper="1.5707963267948966" />

</joint>

<link name="left_shoulder_fe_link">
<visual>
<origin xyz="0.0 0.0 0.06937500000000008" rpy="6.740497088515665e-31 -1.0471975511965979 -1.5707963267948966" />
<geometry>
<mesh filename="./lsa1.1_new//meshes/urdf/obj_combined_hulls/left_shoulder_fe_link.obj" />
</geometry>
</visual>
<collision>
<origin xyz="0.0 0.0 0.06937500000000008" rpy="6.740497088515665e-31 -1.0471975511965979 -1.5707963267948966" />
<geometry>
<mesh filename="./lsa1.1_new//meshes/urdf/obj_combined_hulls/left_shoulder_fe_link.obj" />
</geometry>
</collision>
<inertial>
<origin xyz="-0.018064408329857326 0.021796483466066274 0.07186366456295995" rpy="0 0 0" />
<mass value="0.96" />
<inertia ixx="0.0010839502548898594" ixy="-1.584846344054008e-05" ixz="0.0001626821061471474" iyy="0.001547522617364326" iyz="3.200915124770338e-05" izz="0.0012215774892882657" />
</inertial>
</link>

<joint name="left_shoulder_fe" type="revolute">
<origin xyz="-0.025653371670187414 -0.21558362067624212 0.185419487612475" rpy="-0.5235987755982912 -6.102550324745999e-14 3.1415926535897643" />
<parent link="torso_pitch_upper_link" />
<child link="left_shoulder_fe_link" />
<axis xyz="-5.2164298088153715e-14 1.1728718322156383e-14 0.9999999999999746" />
<limit effort="36" velocity="8.9" lower="-3.141592653589793" upper="0.7853981633974483" />

</joint>

<link name="left_shoulder_motor_link" />

<joint name="left_shoulder_motor" type="fixed">
<origin xyz="-0.00037499999999850153 6.403039926496061e-16 0.06937500000000027" rpy="3.1415926535897922 -1.5707963267948888 0.0" />
<parent link="left_shoulder_fe_link" />
<child link="left_shoulder_motor_link" />
</joint>

<link name="right_shoulder_aa_link">
<visual>
<origin xyz="0.0 2.7755575615628914e-17 -0.031625" rpy="-1.5707963267948966 -6.828148307168349e-30 1.5707963267948966" />
<geometry>
<mesh filename="./lsa1.1_new//meshes/urdf/obj_combined_hulls/right_shoulder_aa_link.obj" />
</geometry>
</visual>
<collision>
<origin xyz="0.0 2.7755575615628914e-17 -0.031625" rpy="-1.5707963267948966 -6.828148307168349e-30 1.5707963267948966" />
<geometry>
<mesh filename="./lsa1.1_new//meshes/urdf/obj_combined_hulls/right_shoulder_aa_link.obj" />
</geometry>
</collision>
<inertial>
<origin xyz="0.07196719932374168 -0.0007098319999853386 -0.031643070370183324" rpy="0 0 0" />
<mass value="0.778" />
<inertia ixx="0.000682161494531174" ixy="-2.2625796921700523e-05" ixz="2.1873666341189004e-06" iyy="0.001996192657199828" iyz="3.7615263729463516e-06" izz="0.0017492429411239572" />
</inertial>
</link>

<joint name="right_shoulder_aa" type="revolute">
<origin xyz="0.031625000000032516 -6.161737786669619e-15 0.06937500000000402" rpy="-1.5707963267951546 0.5235987755984383 -1.5707963267949658" />
<parent link="right_shoulder_fe_link" />
<child link="right_shoulder_aa_link" />
<axis xyz="1.300559538498458e-29 4.614183210861973e-13 0.9999999999999964" />
<limit effort="36" velocity="8.9" lower="-2.0943951023931953" upper="0" />

</joint>

<link name="neck_roll_link">
<visual>
<origin xyz="-1.7618285302889447e-19 -5.551115123125783e-17 6.938893903907228e-18" rpy="-3.1415926535897927 7.050168423664557e-16 -4.295123560541974e-31" />
<geometry>
<mesh filename="./lsa1.1_new//meshes/urdf/obj_combined_hulls/neck_roll_link.obj" />
</geometry>
</visual>
<collision>
<origin xyz="-1.7618285302889447e-19 -5.551115123125783e-17 6.938893903907228e-18" rpy="-3.1415926535897927 7.050168423664557e-16 -4.295123560541974e-31" />
<geometry>
<mesh filename="./lsa1.1_new//meshes/urdf/obj_combined_hulls/neck_roll_link.obj" />
</geometry>
</collision>
<inertial>
<origin xyz="0.010889225000063094 0.05531102518258163 0.020455094945758305" rpy="0 0 0" />
<mass value="0.792" />
<inertia ixx="0.0011107579375322877" ixy="-0.0002158076272142311" ixz="-8.160199392174452e-05" iyy="0.0007183762468522624" iyz="-0.00024884904613905806" izz="0.001156611943648491" />
</inertial>
</link>

<joint name="neck_roll" type="revolute">
<origin xyz="-1.1316241590704837e-15 -0.026999999999999996 0.034499999999999975" rpy="1.5707963267949112 1.2816282966740496e-16 -3.141592653589793" />
<parent link="neck_yaw_link" />
<child link="neck_roll_link" />
<axis xyz="5.638064726918832e-17 -1.5210293746821542e-14 1.0000000000000144" />
<limit effort="19" velocity="8.9" lower="-0.5235987755982988" upper="0.5235987755982988" />

</joint>

<link name="left_shoulder_aa_link">
<visual>
<origin xyz="0.0 0.0 -0.031625" rpy="-1.5707963267948966 -1.2425662754484402e-30 -1.5707963267948966" />
<geometry>
<mesh filename="./lsa1.1_new//meshes/urdf/obj_combined_hulls/left_shoulder_aa_link.obj" />
</geometry>
</visual>
<collision>
<origin xyz="0.0 0.0 -0.031625" rpy="-1.5707963267948966 -1.2425662754484402e-30 -1.5707963267948966" />
<geometry>
<mesh filename="./lsa1.1_new//meshes/urdf/obj_combined_hulls/left_shoulder_aa_link.obj" />
</geometry>
</collision>
<inertial>
<origin xyz="-0.07195179932373885 -0.0006863949999875996 -0.031246740670147308" rpy="0 0 0" />
<mass value="0.7859999999999999" />
<inertia ixx="0.0006892067952639909" ixy="2.3170794598337893e-05" ixz="-9.390221254757445e-06" iyy="0.002020057529194171" iyz="-3.124557984482127e-06" izz="0.0017699018945938512" />
</inertial>
</link>

<joint name="left_shoulder_aa" type="revolute">
<origin xyz="-0.031624999999998515 6.661338147750939e-16 0.06937500000000019" rpy="-1.5707963267948815 -0.5235987755983059 1.570796326794897" />
<parent link="left_shoulder_fe_link" />
<child link="left_shoulder_aa_link" />
<axis xyz="7.631589218041125e-29 -1.8799640275188508e-14 1.0000000000000129" />
<limit effort="36" velocity="8.9" lower="0" upper="2.111848394913139" />

</joint>

<link name="left_bicep_motor_link" />

<joint name="left_bicep_motor" type="fixed">
<origin xyz="-0.09999999999998871 1.9364259755254426e-15 -0.03162499999999994" rpy="1.5707963267948806 -1.1780972450961558 1.570796326794929" />
<parent link="left_shoulder_aa_link" />
<child link="left_bicep_motor_link" />
</joint>

<link name="right_shoulder_ie_link">
<visual>
<origin xyz="0.0 2.7755575615628914e-17 0.12912499999999996" rpy="-3.141592653589793 1.836970198721011e-16 4.5533793101955184e-29" />
<geometry>
<mesh filename="./lsa1.1_new//meshes/urdf/obj_combined_hulls/right_shoulder_ie_link.obj" />
</geometry>
</visual>
<collision>
<origin xyz="0.0 2.7755575615628914e-17 0.12912499999999996" rpy="-3.141592653589793 1.836970198721011e-16 4.5533793101955184e-29" />
<geometry>
<mesh filename="./lsa1.1_new//meshes/urdf/obj_combined_hulls/right_shoulder_ie_link.obj" />
</geometry>
</collision>
<inertial>
<origin xyz="0.0030550354452504387 -0.012093359926407128 0.07601648308677228" rpy="0 0 0" />
<mass value="0.8072296878184448" />
<inertia ixx="0.0019797222594324544" ixy="7.673159251833094e-05" ixz="-0.00018880428345477952" iyy="0.001851577667838464" iyz="0.0002895955851886462" izz="0.0007859102022404687" />
</inertial>
</link>

<joint name="right_shoulder_ie" type="revolute">
<origin xyz="0.12612595250008124 6.439293542825908e-15 -0.031624999999994935" rpy="-3.1415926535897474 -1.5707963267944338 0.0" />
<parent link="right_shoulder_aa_link" />
<child link="right_shoulder_ie_link" />
<axis xyz="-5.20639139448055e-16 3.085185518815391e-16 1.0000000000000189" />
<limit effort="19" velocity="8.9" lower="-1.5707963267948966" upper="1.5707963267948966" />

</joint>

<link name="right_shoulder_tracker_link" />

<joint name="right_shoulder_tracker" type="fixed">
<origin xyz="-0.005040000000000204 0.050999999999999865 0.07152500000000002" rpy="-1.5707963267948966 -1.836970198721011e-16 -3.141592653589793" />
<parent link="right_shoulder_ie_link" />
<child link="right_shoulder_tracker_link" />
</joint>

<link name="neck_pitch_link">
<visual>
<origin xyz="0.0 0.09449999999999997 -0.029" rpy="1.5707963267948966 5.735462992065669e-17 -6.25055564815869e-18" />
<geometry>
<mesh filename="./lsa1.1_new//meshes/urdf/obj_combined_hulls/neck_pitch_link.obj" />
</geometry>
</visual>
<collision>
<origin xyz="0.0 0.09449999999999997 -0.029" rpy="1.5707963267948966 5.735462992065669e-17 -6.25055564815869e-18" />
<geometry>
<mesh filename="./lsa1.1_new//meshes/urdf/obj_combined_hulls/neck_pitch_link.obj" />
</geometry>
</collision>
<inertial>
<origin xyz="-0.0057379563214478195 -0.12818696217586892 -0.02844836731733345" rpy="0 0 0" />
<mass value="2.9268816502772252" />
<inertia ixx="0.005213691615681359" ixy="-0.0006448045184076851" ixz="-2.4805467387907816e-06" iyy="0.00701902338519465" iyz="-0.00014760789631563728" izz="0.006787360121816714" />
</inertial>
</link>

<joint name="neck_pitch" type="revolute">
<origin xyz="0.028999999999999082 0.06000000000000333 0.02699999999999953" rpy="-3.141592653589782 -1.5707963267948735 0.0" />
<parent link="neck_roll_link" />
<child link="neck_pitch_link" />
<axis xyz="-1.874525620950114e-15 1.0147666855111307e-16 0.9999999999999681" />
<limit effort="19" velocity="8.9" lower="-1.2217304763960306" upper="0.7853981633974483" />

</joint>

<link name="zed_mini_right_link" />

<joint name="zed_mini_right" type="fixed">
<origin xyz="-0.08384718756353018 -0.1759398305115566 0.0025000004694319573" rpy="0.1221730476395908 -1.5707963267947564 0.0" />
<parent link="neck_pitch_link" />
<child link="zed_mini_right_link" />
</joint>

<link name="zed_mini_left_link" />

<joint name="zed_mini_left" type="fixed">
<origin xyz="-0.08384718756353515 -0.1759398305115639 -0.060500000469339135" rpy="0.1221730476395908 -1.5707963267947564 0.0" />
<parent link="neck_pitch_link" />
<child link="zed_mini_left_link" />
</joint>

<link name="microphone_link" />

<joint name="microphone" type="fixed">
<origin xyz="-0.06816680778853529 -0.17399923256096408 -0.018042540940563442" rpy="3.0194196059502025 1.5707963267947564 0.0" />
<parent link="neck_pitch_link" />
<child link="microphone_link" />
</joint>

<link name="azure_kinect_center_link" />

<joint name="azure_kinect_center" type="fixed">
<origin xyz="-0.06772835945139169 -0.13843669217856797 -0.02915525987973195" rpy="0.12217304764369845 -1.5707963267941665 0.0" />
<parent link="neck_pitch_link" />
<child link="azure_kinect_center_link" />
</joint>

<link name="azure_kinect_link" />

<joint name="azure_kinect" type="fixed">
<origin xyz="-0.06838343991149627 -0.13851712594522067 0.0007447401202666168" rpy="0.12217304764369845 -1.5707963267941665 0.0" />
<parent link="neck_pitch_link" />
<child link="azure_kinect_link" />
</joint>

<link name="left_shoulder_ie_link">
<visual>
<origin xyz="0.0 0.0 0.129125" rpy="3.141592653589793 1.8369701987210275e-16 -5.29732798467742e-32" />
<geometry>
<mesh filename="./lsa1.1_new//meshes/urdf/obj_combined_hulls/left_shoulder_ie_link.obj" />
</geometry>
</visual>
<collision>
<origin xyz="0.0 0.0 0.129125" rpy="3.141592653589793 1.8369701987210275e-16 -5.29732798467742e-32" />
<geometry>
<mesh filename="./lsa1.1_new//meshes/urdf/obj_combined_hulls/left_shoulder_ie_link.obj" />
</geometry>
</collision>
<inertial>
<origin xyz="0.0030500458368819205 0.01195959700662757 0.07614171634020178" rpy="0 0 0" />
<mass value="0.807229687818445" />
<inertia ixx="0.0019833102584433833" ixy="-7.862108879315832e-05" ixz="-0.00018806247578235987" iyy="0.0018349725973879094" iyz="-0.000293240600144721" izz="0.0007896710920482218" />
</inertial>
</link>

<joint name="left_shoulder_ie" type="revolute">
<origin xyz="-0.1261259524999888 8.881784197001252e-16 -0.031624999999999855" rpy="1.8085242191189497e-14 -1.5707963267948784 0.0" />
<parent link="left_shoulder_aa_link" />
<child link="left_shoulder_ie_link" />
<axis xyz="-6.712245515371906e-16 3.3598018719857576e-16 1.0000000000000238" />
<limit effort="19" velocity="8.9" lower="-1.5707963267948966" upper="1.5707963267948966" />

</joint>

<link name="left_shoulder_tracker_link" />

<joint name="left_shoulder_tracker" type="fixed">
<origin xyz="-0.00504000000000001 -0.051000000000000004 0.07152499999999999" rpy="-1.5707963267948966 1.8369701987210275e-16 -5.29732798467742e-32" />
<parent link="left_shoulder_ie_link" />
<child link="left_shoulder_tracker_link" />
</joint>

<link name="left_elbow_bearing_link" />

<joint name="left_elbow_bearing" type="fixed">
<origin xyz="0.009999999999999655 -0.033500000000002694 0.12912500000000043" rpy="1.5707963267949758 5.0428227778066117e-14 1.0848960618755943e-14" />
<parent link="left_shoulder_ie_link" />
<child link="left_elbow_bearing_link" />
</joint>

<link name="left_elbow_motor_link" />

<joint name="left_elbow_motor" type="fixed">
<origin xyz="0.00999999999999993 -0.00012499999999766517 0.12912499999999774" rpy="1.5707963267950151 0.837764194475241 8.757646092288882e-14" />
<parent link="left_shoulder_ie_link" />
<child link="left_elbow_motor_link" />
</joint>

<link name="right_elbow_fe_link">
<visual>
<origin xyz="-2.7755575615628914e-17 0.010000000000000002 -0.026249999999999996" rpy="1.5707963267948966 3.390113629309306e-30 -1.5707963267948966" />
<geometry>
<mesh filename="./lsa1.1_new//meshes/urdf/obj_combined_hulls/right_elbow_fe_link.obj" />
</geometry>
</visual>
<collision>
<origin xyz="-2.7755575615628914e-17 0.010000000000000002 -0.026249999999999996" rpy="1.5707963267948966 3.390113629309306e-30 -1.5707963267948966" />
<geometry>
<mesh filename="./lsa1.1_new//meshes/urdf/obj_combined_hulls/right_elbow_fe_link.obj" />
</geometry>
</collision>
<inertial>
<origin xyz="0.06479056646004125 0.01118032668962237 -0.027502317500050166" rpy="0 0 0" />
<mass value="0.672" />
<inertia ixx="0.0004416806496044859" ixy="4.612887669291204e-05" ixz="-4.640819082345558e-05" iyy="0.0011042143804110072" iyz="-4.709754667063635e-06" izz="0.0010572810341188256" />
</inertial>
</link>

<joint name="right_elbow_fe" type="revolute">
<origin xyz="0.009999835019501649 -0.02600095250001952 0.1291249803636178" rpy="1.5707963267945642 -1.5707963267947342 0.0" />
<parent link="right_shoulder_ie_link" />
<child link="right_elbow_fe_link" />
<axis xyz="2.1619553916403353e-29 3.4295401762622856e-17 1.0000000000000022" />
<limit effort="19" velocity="8.9" lower="-2.6179938779914944" upper="0.17453292519943295" />

</joint>

<link name="right_forearm_tracker_link" />

<joint name="right_forearm_tracker" type="fixed">
<origin xyz="0.07549999999999997 0.015549460985616001 -0.07774999999999999" rpy="-1.852937997734199e-19 -3.390147667228127e-30 1.5707963267948966" />
<parent link="right_elbow_fe_link" />
<child link="right_forearm_tracker_link" />
</joint>

<link name="left_elbow_fe_link">
<visual>
<origin xyz="-0.009999999999999995 0.0 -0.026249999999999996" rpy="-1.5707963267948966 3.4658797310181623e-31 0.0" />
<geometry>
<mesh filename="./lsa1.1_new//meshes/urdf/obj_combined_hulls/left_elbow_fe_link.obj" />
</geometry>
</visual>
<collision>
<origin xyz="-0.009999999999999995 0.0 -0.026249999999999996" rpy="-1.5707963267948966 3.4658797310181623e-31 0.0" />
<geometry>
<mesh filename="./lsa1.1_new//meshes/urdf/obj_combined_hulls/left_elbow_fe_link.obj" />
</geometry>
</collision>
<inertial>
<origin xyz="-0.01118808547904041 -0.06443605627779016 -0.026319916135813252" rpy="0 0 0" />
<mass value="0.6840401167420422" />
<inertia ixx="0.0011341436749277153" ixy="4.607894457486835e-05" ixz="2.240967970923843e-06" iyy="0.0004551294238640585" iyz="1.5807375057063412e-05" izz="0.0010784451301199087" />
</inertial>
</link>

<joint name="left_elbow_fe" type="revolute">
<origin xyz="0.009999999999999488 0.0260009525000017 0.1291250000000003" rpy="-1.5707963267948144 -7.494295571202647e-09 2.3217948891511006e-15" />
<parent link="left_shoulder_ie_link" />
<child link="left_elbow_fe_link" />
<axis xyz="-1.9732850551217684e-15 4.223533854071992e-16 1.0000000000000315" />
<limit effort="19" velocity="8.9" lower="-0.17453292519943295" upper="2.6179938779914944" />

</joint>

<link name="left_forearm_tracker_link" />

<joint name="left_forearm_tracker" type="fixed">
<origin xyz="-0.007549460985615994 -0.0755 -0.07774999999999999" rpy="-1.8529379978508901e-19 3.466220110206375e-31 -6.307015315174871e-54" />
<parent link="left_elbow_fe_link" />
<child link="left_forearm_tracker_link" />
</joint>

<link name="left_forearm_motor_link" />

<joint name="left_forearm_motor" type="fixed">
<origin xyz="-0.009999950835108738 -0.08262500000001435 -0.026250158704031454" rpy="-1.5707963267948908 -0.4188790204786378 -1.1505670175351315e-14" />
<parent link="left_elbow_fe_link" />
<child link="left_forearm_motor_link" />
</joint>

<link name="right_wrist_rotation_link">
<visual>
<origin xyz="0.0 0.0 6.938893903907228e-18" rpy="-3.141592653589793 2.5421260299864258e-30 1.2862303347851033e-30" />
<geometry>
<mesh filename="./lsa1.1_new//meshes/urdf/obj_combined_hulls/right_wrist_rotation_link.obj" />
</geometry>
</visual>
<collision>
<origin xyz="0.0 0.0 6.938893903907228e-18" rpy="-3.141592653589793 2.5421260299864258e-30 1.2862303347851033e-30" />
<geometry>
<mesh filename="./lsa1.1_new//meshes/urdf/obj_combined_hulls/right_wrist_rotation_link.obj" />
</geometry>
</collision>
<inertial>
<origin xyz="0.013932888268054104 -0.0002769051302899672 0.03586731395994533" rpy="0 0 0" />
<mass value="0.746" />
<inertia ixx="0.0009304154282668103" ixy="-1.4187291183130974e-05" ixz="-4.719506172503191e-05" iyy="0.0010219861460921522" iyz="-8.560399287826932e-07" izz="0.0004909679289931075" />
</inertial>
</link>

<joint name="right_wrist_rotation" type="revolute">
<origin xyz="0.10875095250009138 0.009999914957652428 -0.026250142730359804" rpy="-1.5707963267949576 1.0843404446966898e-13 -1.570796326794919" />
<parent link="right_elbow_fe_link" />
<child link="right_wrist_rotation_link" />
<axis xyz="7.977414277479792e-16 -4.1361313892512067e-16 0.9999999999999591" />
<limit effort="19" velocity="8.9" lower="-1.5707963267948966" upper="1.5707963267948966" />

</joint>

<link name="left_wrist_rotation_link">
<visual>
<origin xyz="6.938893903907228e-18 2.7755575615628914e-17 0.0" rpy="3.141592653589793 4.506315468407392e-25 3.141592653589793" />
<geometry>
<mesh filename="./lsa1.1_new//meshes/urdf/obj_combined_hulls/left_wrist_rotation_link.obj" />
</geometry>
</visual>
<collision>
<origin xyz="6.938893903907228e-18 2.7755575615628914e-17 0.0" rpy="3.141592653589793 4.506315468407392e-25 3.141592653589793" />
<geometry>
<mesh filename="./lsa1.1_new//meshes/urdf/obj_combined_hulls/left_wrist_rotation_link.obj" />
</geometry>
</collision>
<inertial>
<origin xyz="0.014712460248640626 0.0002709453040638521 0.03585329428842248" rpy="0 0 0" />
<mass value="0.736" />
<inertia ixx="0.0009144720128498236" ixy="1.7238115557206555e-05" ixz="-6.752004945833398e-05" iyy="0.0009868872822093174" iyz="6.108396179557146e-08" izz="0.00046042942469568036" />
</inertial>
</link>

<joint name="left_wrist_rotation" type="revolute">
<origin xyz="-0.009999950835108719 -0.10875095250001376 -0.026250158704030385" rpy="1.5707963267949039 1.5690334341245393e-15 -6.970966133129732e-15" />
<parent link="left_elbow_fe_link" />
<child link="left_wrist_rotation_link" />
<axis xyz="4.506315468484828e-25 1.3740748865679865e-16 0.999999999999973" />
<limit effort="19" velocity="8.9" lower="-1.5707963267948966" upper="1.5707963267948966" />

</joint>

<link name="left_wrist_motor_link" />

<joint name="left_wrist_motor" type="fixed">
<origin xyz="-0.007884049999995167 -8.458586118971487e-16 0.04950000000001319" rpy="1.5707963267947815 0.6544984694978567 -1.570796326794965" />
<parent link="left_wrist_rotation_link" />
<child link="left_wrist_motor_link" />
</joint>

<link name="left_lower_wrist_bearing_link" />

<joint name="left_lower_wrist_bearing" type="fixed">
<origin xyz="0.02907500000000891 -2.6118225204124716e-15 0.12250000000002623" rpy="1.5707963267948881 7.216449665367594e-15 -1.570796326794896" />
<parent link="left_wrist_rotation_link" />
<child link="left_lower_wrist_bearing_link" />
</joint>

<link name="left_upper_wrist_bearing_link" />

<joint name="left_upper_wrist_bearing" type="fixed">
<origin xyz="0.026541902500004214 -0.024000000000001354 0.04950000000001035" rpy="1.5707963267948022 0.29670597283904204 -1.5707963267949256" />
<parent link="left_wrist_rotation_link" />
<child link="left_upper_wrist_bearing_link" />
</joint>

<link name="right_wrist_flexion_link">
<visual>
<origin xyz="0.0 -0.1225 0.016990950000000005" rpy="1.5707963267948966 1.5707963267948966 0.0" />
<geometry>
<mesh filename="./lsa1.1_new//meshes/urdf/obj_combined_hulls/right_wrist_flexion_link.obj" />
</geometry>
</visual>
<collision>
<origin xyz="0.0 -0.1225 0.016990950000000005" rpy="1.5707963267948966 1.5707963267948966 0.0" />
<geometry>
<mesh filename="./lsa1.1_new//meshes/urdf/obj_combined_hulls/right_wrist_flexion_link.obj" />
</geometry>
</collision>
<inertial>
<origin xyz="0.005295774683642261 0.04774105497029693 0.01659051997466799" rpy="0 0 0" />
<mass value="0.45249242436677656" />
<inertia ixx="0.0007976521578044414" ixy="-5.4027437508803006e-05" ixz="-1.703772251806697e-05" iyy="0.0002536937960376567" iyz="-2.982870641285682e-05" izz="0.0006965251193833308" />
</inertial>
</link>

<joint name="right_wrist_flexion" type="revolute">
<origin xyz="0.017000000000030484 1.0352829704629585e-14 0.1225000000001022" rpy="1.5707963267948966 -9.220294051054228e-29 -1.5707963267948954" />
<parent link="right_wrist_rotation_link" />
<child link="right_wrist_flexion_link" />
<axis xyz="1.1906708258248518e-15 1.1102230243724724e-16 1.0000000000000002" />
<limit effort="19" velocity="8.9" lower="-1.0471975511965976" upper="0.7853981633974483" />

</joint>

<link name="right_haptx_dorsal_tracker_link" />

<joint name="right_haptx_dorsal_tracker" type="fixed">
<origin xyz="-0.039000000000000465 -0.04000000000001519 -0.033965997709253265" rpy="1.4449940227302047e-29 -0.5235987755982986 3.1415926535897882" />
<parent link="right_wrist_flexion_link" />
<child link="right_haptx_dorsal_tracker_link" />
</joint>

<link name="right_haptx_origin_tracker_link" />

<joint name="right_haptx_origin_tracker" type="fixed">
<origin xyz="-0.0022999999999957204 0.10050178325275509 0.0075000000000092935" rpy="-1.5707963267948482 -1.3819474587923648e-13 1.570796326794817" />
<parent link="right_wrist_flexion_link" />
<child link="right_haptx_origin_tracker_link" />
</joint>

<link name="right_dorsal_tracker_link" />

<joint name="right_dorsal_tracker" type="fixed">
<origin xyz="-0.04584865121309785 0.05406848916449099 0.0202093090093367" rpy="3.141592653589708 -1.5707963267947525 0.0" />
<parent link="right_wrist_flexion_link" />
<child link="right_dorsal_tracker_link" />
</joint>

<link name="right_grip_point_link" />

<joint name="right_grip_point" type="fixed">
<origin xyz="0.04715134878690774 0.1540684891644804 0.020209309009345675" rpy="3.141592653589708 -1.5707963267947525 0.0" />
<parent link="right_wrist_flexion_link" />
<child link="right_grip_point_link" />
</joint>

<link name="left_wrist_flexion_link">
<visual>
<origin xyz="2.7755575615628914e-17 -0.12250000000000003 0.016990950000000005" rpy="1.5707963267948966 -1.5707963267948966 0.0" />
<geometry>
<mesh filename="./lsa1.1_new//meshes/urdf/obj_combined_hulls/left_wrist_flexion_link.obj" />
</geometry>
</visual>
<collision>
<origin xyz="2.7755575615628914e-17 -0.12250000000000003 0.016990950000000005" rpy="1.5707963267948966 -1.5707963267948966 0.0" />
<geometry>
<mesh filename="./lsa1.1_new//meshes/urdf/obj_combined_hulls/left_wrist_flexion_link.obj" />
</geometry>
</collision>
<inertial>
<origin xyz="-0.007214093813734281 0.047477478114136336 0.01659403350791623" rpy="0 0 0" />
<mass value="0.4524910213104889" />
<inertia ixx="0.0008149412381862845" ixy="-7.607233905240332e-06" ixz="2.6993710660141486e-06" iyy="0.0002432454250374737" iyz="-2.9408951481029545e-05" izz="0.0007034047478510397" />
</inertial>
</link>

<joint name="left_wrist_flexion" type="revolute">
<origin xyz="0.01700000000000891 -2.6367796834847468e-15 0.1225000000000264" rpy="1.5707963267948881 7.216449665704985e-15 -1.570796326794896" />
<parent link="left_wrist_rotation_link" />
<child link="left_wrist_flexion_link" />
<axis xyz="-3.8180743855988356e-17 -4.163340929466663e-17 1.0000000000000007" />
<limit effort="19" velocity="8.9" lower="-0.7853981633974483" upper="1.0471975511965976" />

</joint>

<link name="left_haptx_dorsal_tracker_link" />

<joint name="left_haptx_dorsal_tracker" type="fixed">
<origin xyz="0.03899999999999795 -0.040000000000010305 -0.03397504770924921" rpy="-4.0279062320866104e-14 0.5235987755982986 3.141592653589769" />
<parent link="left_wrist_flexion_link" />
<child link="left_haptx_dorsal_tracker_link" />
</joint>

<link name="left_haptx_origin_tracker_link" />

<joint name="left_haptx_origin_tracker" type="fixed">
<origin xyz="0.0022999999999973875 0.10050178325275903 0.007490950000005371" rpy="1.570796326794964 -2.7680688860990577e-14 1.5707963267949303" />
<parent link="left_wrist_flexion_link" />
<child link="left_haptx_origin_tracker_link" />
</joint>

<link name="left_dorsal_tracker_link" />

<joint name="left_dorsal_tracker" type="fixed">
<origin xyz="0.04584865121309827 0.05406848916449568 0.014620259009333053" rpy="3.141592653589762 1.5707963267948226 0.0" />
<parent link="left_wrist_flexion_link" />
<child link="left_dorsal_tracker_link" />
</joint>

<link name="left_grip_point_link" />

<joint name="left_grip_point" type="fixed">
<origin xyz="-0.04715134878690145 0.1540684891644907 0.014620259009341921" rpy="3.141592653589762 1.5707963267948226 0.0" />
<parent link="left_wrist_flexion_link" />
<child link="left_grip_point_link" />
</joint>

<link name="left_palm_link" />

<joint name="left_palm" type="fixed">
<origin xyz="-0.0233000000000026 0.09800178325275868 0.016990950000006583" rpy="3.0832052996876315e-14 -1.5707963267948244 0.0" />
<parent link="left_wrist_flexion_link" />
<child link="left_palm_link" />
</joint>

<link name="right_middle_finger_mcp_abduction_link">
<visual>
<origin xyz="0.0 -0.0050000000000000044 2.7755575615628914e-17" rpy="-4.776889756388367e-30 7.108538126311427e-30 9.146243139419362e-33" />
<geometry>
<mesh filename="./lsa1.1_new//meshes/urdf/obj_combined_hulls/right_middle_finger_mcp_abduction_link.obj" />
</geometry>
</visual>
<collision>
<origin xyz="0.0 -0.0050000000000000044 2.7755575615628914e-17" rpy="-4.776889756388367e-30 7.108538126311427e-30 9.146243139419362e-33" />
<geometry>
<mesh filename="./lsa1.1_new//meshes/urdf/obj_combined_hulls/right_middle_finger_mcp_abduction_link.obj" />
</geometry>
</collision>
<inertial>
<origin xyz="2.2167138630326815e-05 0.00278362281118332 -0.0026015173229284676" rpy="0 0 0" />
<mass value="0.008033364303465346" />
<inertia ixx="2.5922752158806076e-07" ixy="-5.71079300583445e-10" ixz="3.8593237498142035e-10" iyy="2.398548619041403e-07" iyz="5.473634720550702e-09" izz="1.6158238417482518e-07" />
</inertial>
</link>

<joint name="right_middle_finger_mcp_abduction" type="revolute">
<origin xyz="0.003000000000004055 0.10050178325275405 0.007500000000136363" rpy="3.1415926535897873 1.5707963267947316 0.0" />
<parent link="right_wrist_flexion_link" />
<child link="right_middle_finger_mcp_abduction_link" />
<axis xyz="-3.235208709338925e-29 9.668008308765116e-14 1.000000000000009" />
<limit effort="30" velocity="30" lower="-0.3490658503988659" upper="0.3490658503988659" />

</joint>

<link name="right_pinkie_finger_mcp_abduction_link">
<visual>
<origin xyz="0.0 -0.004999999999999977 -2.7755575615628914e-17" rpy="-1.0438478552240215e-29 2.7588300477159354e-30 -9.103224237861447e-31" />
<geometry>
<mesh filename="./lsa1.1_new//meshes/urdf/obj_combined_hulls/right_pinkie_finger_mcp_abduction_link.obj" />
</geometry>
</visual>
<collision>
<origin xyz="0.0 -0.004999999999999977 -2.7755575615628914e-17" rpy="-1.0438478552240215e-29 2.7588300477159354e-30 -9.103224237861447e-31" />
<geometry>
<mesh filename="./lsa1.1_new//meshes/urdf/obj_combined_hulls/right_pinkie_finger_mcp_abduction_link.obj" />
</geometry>
</collision>
<inertial>
<origin xyz="2.2167138630327083e-05 0.002783622811183347 -0.002601517322928524" rpy="0 0 0" />
<mass value="0.008033364303465346" />
<inertia ixx="2.5922752158806076e-07" ixy="-5.710793005834631e-10" ixz="3.8593237498143136e-10" iyy="2.3985486190414046e-07" iyz="5.473634720550702e-09" izz="1.6158238417482502e-07" />
</inertial>
</link>

<joint name="right_pinkie_finger_mcp_abduction" type="revolute">
<origin xyz="0.003000000000005998 0.09850178325274836 0.045500000000133496" rpy="3.141592653589792 1.5707963267947505 0.0" />
<parent link="right_wrist_flexion_link" />
<child link="right_pinkie_finger_mcp_abduction_link" />
<axis xyz="-2.7588300477159354e-30 9.163658144173458e-14 1.0" />
<limit effort="30" velocity="30" lower="-0.3490658503988659" upper="0.3490658503988659" />

</joint>

<link name="right_index_finger_mcp_abduction_link">
<visual>
<origin xyz="0.0 -0.0050000000000000044 -2.7755575615628914e-17" rpy="-5.493420561510654e-29 1.78548043511012e-32 -9.103224237861223e-31" />
<geometry>
<mesh filename="./lsa1.1_new//meshes/urdf/obj_combined_hulls/right_index_finger_mcp_abduction_link.obj" />
</geometry>
</visual>
<collision>
<origin xyz="0.0 -0.0050000000000000044 -2.7755575615628914e-17" rpy="-5.493420561510654e-29 1.78548043511012e-32 -9.103224237861223e-31" />
<geometry>
<mesh filename="./lsa1.1_new//meshes/urdf/obj_combined_hulls/right_index_finger_mcp_abduction_link.obj" />
</geometry>
</collision>
<inertial>
<origin xyz="2.2167138630289807e-05 0.0027836228111833205 -0.0026015173229285036" rpy="0 0 0" />
<mass value="0.008033364303465346" />
<inertia ixx="2.5922752158806076e-07" ixy="-5.710793005837549e-10" ixz="3.859323749808923e-10" iyy="2.398548619041384e-07" iyz="5.4736347205508524e-09" izz="1.6158238417482296e-07" />
</inertial>
</link>

<joint name="right_index_finger_mcp_abduction" type="revolute">
<origin xyz="0.0030000000000031113 0.09950178325275438 -0.011499999999989956" rpy="-3.141592653589708 1.5707963267947505 0.0" />
<parent link="right_wrist_flexion_link" />
<child link="right_index_finger_mcp_abduction_link" />
<axis xyz="-1.7854804344855905e-32 -2.661114771897525e-26 1.0" />
<limit effort="30" velocity="30" lower="-0.3490658503988659" upper="0.3490658503988659" />

</joint>

<link name="right_ring_finger_mcp_abduction_link">
<visual>
<origin xyz="0.0 -0.005000000000000032 -2.7755575615628914e-17" rpy="-3.79475265360824e-29 3.5550463092882275e-30 -1.0535087677337404e-30" />
<geometry>
<mesh filename="./lsa1.1_new//meshes/urdf/obj_combined_hulls/right_ring_finger_mcp_abduction_link.obj" />
</geometry>
</visual>
<collision>
<origin xyz="0.0 -0.005000000000000032 -2.7755575615628914e-17" rpy="-3.79475265360824e-29 3.5550463092882275e-30 -1.0535087677337404e-30" />
<geometry>
<mesh filename="./lsa1.1_new//meshes/urdf/obj_combined_hulls/right_ring_finger_mcp_abduction_link.obj" />
</geometry>
</collision>
<inertial>
<origin xyz="2.2167138630337085e-05 0.0027836228111832867 -0.002601517322928524" rpy="0 0 0" />
<mass value="0.008033364303465346" />
<inertia ixx="2.592275215880608e-07" ixy="-5.710793005833666e-10" ixz="3.8593237498141295e-10" iyy="2.398548619041409e-07" iyz="5.473634720550722e-09" izz="1.615823841748258e-07" />
</inertial>
</link>

<joint name="right_ring_finger_mcp_abduction" type="revolute">
<origin xyz="0.0030000000000050264 0.09950178325274919 0.02650000000000762" rpy="-3.141592653589703 1.5707963267947505 0.0" />
<parent link="right_wrist_flexion_link" />
<child link="right_ring_finger_mcp_abduction_link" />
<axis xyz="-1.1715101666110718e-28 4.821457041045029e-15 1.0000000000000093" />
<limit effort="30" velocity="30" lower="-0.3490658503988659" upper="0.3490658503988659" />

</joint>

<link name="right_thumb_opposition_link">
<visual>
<origin xyz="0.0 0.019999999999999976 -0.0025000000000000577" rpy="-1.5707963267948966 2.345472529656524e-29 6.472872104732229e-30" />
<geometry>
<mesh filename="./lsa1.1_new//meshes/urdf/obj_combined_hulls/right_thumb_opposition_link.obj" />
</geometry>
</visual>
<collision>
<origin xyz="0.0 0.019999999999999976 -0.0025000000000000577" rpy="-1.5707963267948966 2.345472529656524e-29 6.472872104732229e-30" />
<geometry>
<mesh filename="./lsa1.1_new//meshes/urdf/obj_combined_hulls/right_thumb_opposition_link.obj" />
</geometry>
</collision>
<inertial>
<origin xyz="-0.0007825484852760822 0.00439699544823534 -0.004804276744802365" rpy="0 0 0" />
<mass value="0.009841931053884784" />
<inertia ixx="1.0545152324306868e-06" ixy="-3.15436564779023e-08" ixz="6.725772016358923e-08" iyy="8.965614463882282e-07" iyz="4.946301974292744e-08" izz="3.65721515188733e-07" />
</inertial>
</link>

<joint name="right_thumb_opposition" type="revolute">
<origin xyz="0.020000000000000073 0.0519999999999913 -0.004193480880562029" rpy="-1.5707963267947609 5.028202236315286e-14 -9.034530555669631e-14" />
<parent link="right_wrist_flexion_link" />
<child link="right_thumb_opposition_link" />
<axis xyz="5.1545239483897906e-15 -1.617755209205452e-14 0.9999999999999505" />
<limit effort="30" velocity="30" lower="-0.7853981633974483" upper="0" />

</joint>

<link name="left_thumb_opposition_link">
<visual>
<origin xyz="2.7755575615628914e-17 0.019999999999999983 -0.00250000000000003" rpy="-1.5707963267948966 -2.8822464224142208e-30 -1.3953077324044914e-29" />
<geometry>
<mesh filename="./lsa1.1_new//meshes/urdf/obj_combined_hulls/left_thumb_opposition_link.obj" />
</geometry>
</visual>
<collision>
<origin xyz="2.7755575615628914e-17 0.019999999999999983 -0.00250000000000003" rpy="-1.5707963267948966 -2.8822464224142208e-30 -1.3953077324044914e-29" />
<geometry>
<mesh filename="./lsa1.1_new//meshes/urdf/obj_combined_hulls/left_thumb_opposition_link.obj" />
</geometry>
</collision>
<inertial>
<origin xyz="0.0007825484852761146 0.004396995448235397 -0.004804276744802321" rpy="0 0 0" />
<mass value="0.009841931053884784" />
<inertia ixx="1.0545152324306756e-06" ixy="3.154365647790262e-08" ixz="-6.725772016358849e-08" iyy="8.965614463882236e-07" iyz="4.946301974293154e-08" izz="3.657215151887293e-07" />
</inertial>
</link>

<joint name="left_thumb_opposition" type="revolute">
<origin xyz="-0.02000000000000232 0.05199999999999652 -0.004202530880559004" rpy="-1.570796326794871 6.678756810608639e-14 2.93289619548154e-14" />
<parent link="left_wrist_flexion_link" />
<child link="left_thumb_opposition_link" />
<axis xyz="2.0313863903961682e-15 8.309248633081657e-16 0.999999999999989" />
<limit effort="30" velocity="30" lower="0" upper="0.7853981633974483" />

</joint>

<link name="left_middle_finger_mcp_abduction_link">
<visual>
<origin xyz="-6.938893903907228e-18 -0.0050000000000000044 0.0" rpy="1.046059678011391e-29 4.0621201810957394e-30 -9.71153743924765e-27" />
<geometry>
<mesh filename="./lsa1.1_new//meshes/urdf/obj_combined_hulls/left_middle_finger_mcp_abduction_link.obj" />
</geometry>
</visual>
<collision>
<origin xyz="-6.938893903907228e-18 -0.0050000000000000044 0.0" rpy="1.046059678011391e-29 4.0621201810957394e-30 -9.71153743924765e-27" />
<geometry>
<mesh filename="./lsa1.1_new//meshes/urdf/obj_combined_hulls/left_middle_finger_mcp_abduction_link.obj" />
</geometry>
</collision>
<inertial>
<origin xyz="2.216713863032078e-05 0.0027836228111833192 -0.002601517322928495" rpy="0 0 0" />
<mass value="0.008033364303465346" />
<inertia ixx="2.592275215880608e-07" ixy="-5.710793005834737e-10" ixz="3.8593237498142443e-10" iyy="2.3985486190414046e-07" iyz="5.473634720550708e-09" izz="1.6158238417482505e-07" />
</inertial>
</link>

<joint name="left_middle_finger_mcp_abduction" type="revolute">
<origin xyz="-0.0030000000000024174 0.10050178325275891 0.007490950000005728" rpy="-3.1415926535897607 -1.5707963267948222 0.0" />
<parent link="left_wrist_flexion_link" />
<child link="left_middle_finger_mcp_abduction_link" />
<axis xyz="2.4426627101297826e-24 3.330669185530842e-16 0.9999999999999998" />
<limit effort="30" velocity="30" lower="-0.3490658503988659" upper="0.3490658503988659" />

</joint>

<link name="left_pinkie_finger_mcp_abduction_link">
<visual>
<origin xyz="0.0 -0.0050000000000000044 0.0" rpy="-2.6864630320400566e-30 9.796798552187728e-31 -4.952941554636777e-25" />
<geometry>
<mesh filename="./lsa1.1_new//meshes/urdf/obj_combined_hulls/left_pinkie_finger_mcp_abduction_link.obj" />
</geometry>
</visual>
<collision>
<origin xyz="0.0 -0.0050000000000000044 0.0" rpy="-2.6864630320400566e-30 9.796798552187728e-31 -4.952941554636777e-25" />
<geometry>
<mesh filename="./lsa1.1_new//meshes/urdf/obj_combined_hulls/left_pinkie_finger_mcp_abduction_link.obj" />
</geometry>
</collision>
<inertial>
<origin xyz="2.2167138630361215e-05 0.0027836228111833197 -0.002601517322928495" rpy="0 0 0" />
<mass value="0.008033364303465346" />
<inertia ixx="2.592275215880608e-07" ixy="-5.710793005831871e-10" ixz="3.859323749814364e-10" iyy="2.398548619041424e-07" iyz="5.473634720550701e-09" izz="1.6158238417482695e-07" />
</inertial>
</link>

<joint name="left_pinkie_finger_mcp_abduction" type="revolute">
<origin xyz="-0.0029999999999995586 0.09850178325275749 0.04549095000000401" rpy="-3.141592653589762 -1.5707963267948208 0.0" />
<parent link="left_wrist_flexion_link" />
<child link="left_pinkie_finger_mcp_abduction_link" />
<axis xyz="1.0160338004455636e-16 -1.8093414911904835e-15 0.9999999999999691" />
<limit effort="30" velocity="30" lower="-0.3490658503988659" upper="0.3490658503988659" />

</joint>

<link name="left_index_finger_mcp_abduction_link">
<visual>
<origin xyz="-6.938893903907228e-18 -0.0050000000000000044 2.7755575615628914e-17" rpy="1.4500067676698927e-29 -1.9713423396215304e-30 9.711650107098243e-27" />
<geometry>
<mesh filename="./lsa1.1_new//meshes/urdf/obj_combined_hulls/left_index_finger_mcp_abduction_link.obj" />
</geometry>
</visual>
<collision>
<origin xyz="-6.938893903907228e-18 -0.0050000000000000044 2.7755575615628914e-17" rpy="1.4500067676698927e-29 -1.9713423396215304e-30 9.711650107098243e-27" />
<geometry>
<mesh filename="./lsa1.1_new//meshes/urdf/obj_combined_hulls/left_index_finger_mcp_abduction_link.obj" />
</geometry>
</collision>
<inertial>
<origin xyz="2.2167138630320188e-05 0.0027836228111833223 -0.0026015173229284472" rpy="0 0 0" />
<mass value="0.008033364303465346" />
<inertia ixx="2.592275215880606e-07" ixy="-5.710793005835508e-10" ixz="3.85932374980869e-10" iyy="2.3985486190414046e-07" iyz="5.4736347205508524e-09" izz="1.61582384174825e-07" />
</inertial>
</link>

<joint name="left_index_finger_mcp_abduction" type="revolute">
<origin xyz="-0.0030000000000034166 0.09950178325275838 -0.011509049999993175" rpy="-3.1415926535897625 -1.5707963267948208 0.0" />
<parent link="left_wrist_flexion_link" />
<child link="left_index_finger_mcp_abduction_link" />
<axis xyz="-5.78074549856792e-24 -3.3306689014377964e-16 1.0000000000000002" />
<limit effort="30" velocity="30" lower="-0.3490658503988659" upper="0.3490658503988659" />

</joint>

<link name="left_ring_finger_mcp_abduction_link">
<visual>
<origin xyz="0.0 -0.0050000000000000044 0.0" rpy="4.0212954893214336e-30 7.560781039057134e-30 -7.477970582502699e-25" />
<geometry>
<mesh filename="./lsa1.1_new//meshes/urdf/obj_combined_hulls/left_ring_finger_mcp_abduction_link.obj" />
</geometry>
</visual>
<collision>
<origin xyz="0.0 -0.0050000000000000044 0.0" rpy="4.0212954893214336e-30 7.560781039057134e-30 -7.477970582502699e-25" />
<geometry>
<mesh filename="./lsa1.1_new//meshes/urdf/obj_combined_hulls/left_ring_finger_mcp_abduction_link.obj" />
</geometry>
</collision>
<inertial>
<origin xyz="2.2167138630335472e-05 0.002783622811183314 -0.0026015173229284945" rpy="0 0 0" />
<mass value="0.008033364303465346" />
<inertia ixx="2.5922752158806086e-07" ixy="-5.710793005833477e-10" ixz="3.85932374981458e-10" iyy="2.39854861904141e-07" iyz="5.473634720550727e-09" izz="1.615823841748256e-07" />
</inertial>
</link>

<joint name="left_ring_finger_mcp_abduction" type="revolute">
<origin xyz="-0.0030000000000007243 0.09950178325275846 0.026490950000004593" rpy="-3.141592653589762 -1.5707963267948213 0.0" />
<parent link="left_wrist_flexion_link" />
<child link="left_ring_finger_mcp_abduction_link" />
<axis xyz="4.901817541872241e-16 -1.474532162487971e-15 0.9999999999999838" />
<limit effort="30" velocity="30" lower="-0.3490658503988659" upper="0.3490658503988659" />

</joint>

<link name="right_middle_finger_mcp_flexion_link">
<visual>
<origin xyz="-0.0050000000000000044 0.0 -6.938893903907228e-18" rpy="-1.5707963267948966 -1.5707963267948966 0.0" />
<geometry>
<mesh filename="./lsa1.1_new//meshes/urdf/obj_combined_hulls/right_middle_finger_mcp_flexion_link.obj" />
</geometry>
</visual>
<collision>
<origin xyz="-0.0050000000000000044 0.0 -6.938893903907228e-18" rpy="-1.5707963267948966 -1.5707963267948966 0.0" />
<geometry>
<mesh filename="./lsa1.1_new//meshes/urdf/obj_combined_hulls/right_middle_finger_mcp_flexion_link.obj" />
</geometry>
</collision>
<inertial>
<origin xyz="-0.004711241977214683 0.002632433941056846 -0.00010618381221108387" rpy="0 0 0" />
<mass value="0.008551500024267173" />
<inertia ixx="4.4703652121635063e-07" ixy="-7.399789963729793e-10" ixz="-2.6222867037387065e-10" iyy="4.899247390003302e-07" iyz="-2.389071697354312e-09" izz="2.833370437831566e-07" />
</inertial>
</link>

<joint name="right_middle_finger_mcp_flexion" type="revolute">
<origin xyz="0.0 0.0 2.7755575615628914e-17" rpy="1.5707963267948966 -1.0162164695463902e-13 1.5707963267948801" />
<parent link="right_middle_finger_mcp_abduction_link" />
<child link="right_middle_finger_mcp_flexion_link" />
<axis xyz="-1.6510618999422594e-14 9.547918011766381e-15 1.0000000000000089" />
<limit effort="30" velocity="30" lower="-0.2617993877991494" upper="0.7853981633974483" />

</joint>

<link name="right_pinkie_finger_mcp_flexion_link">
<visual>
<origin xyz="-0.004999999999999977 -2.7755575615628914e-17 1.3877787807814457e-17" rpy="-1.5707963267948966 -1.5707963267948966 0.0" />
<geometry>
<mesh filename="./lsa1.1_new//meshes/urdf/obj_combined_hulls/right_pinkie_finger_mcp_flexion_link.obj" />
</geometry>
</visual>
<collision>
<origin xyz="-0.004999999999999977 -2.7755575615628914e-17 1.3877787807814457e-17" rpy="-1.5707963267948966 -1.5707963267948966 0.0" />
<geometry>
<mesh filename="./lsa1.1_new//meshes/urdf/obj_combined_hulls/right_pinkie_finger_mcp_flexion_link.obj" />
</geometry>
</collision>
<inertial>
<origin xyz="-0.004711241977214655 0.0026324339410568067 -0.00010618381221106775" rpy="0 0 0" />
<mass value="0.008551500024267173" />
<inertia ixx="4.470365212163509e-07" ixy="-7.399789963728778e-10" ixz="-2.6222867037372894e-10" iyy="4.899247390003302e-07" iyz="-2.3890716973543828e-09" izz="2.833370437831569e-07" />
</inertial>
</link>

<joint name="right_pinkie_finger_mcp_flexion" type="revolute">
<origin xyz="0.0 2.7755575615628914e-17 -2.7755575615628914e-17" rpy="1.5707963267948966 -9.173851922105761e-14 1.5707963267948966" />
<parent link="right_pinkie_finger_mcp_abduction_link" />
<child link="right_pinkie_finger_mcp_flexion_link" />
<axis xyz="2.849002483033517e-28 2.5941490464384724e-25 1.0" />
<limit effort="30" velocity="30" lower="-0.2617993877991494" upper="0.7853981633974483" />

</joint>

<link name="right_index_finger_mcp_flexion_link">
<visual>
<origin xyz="-0.004999999999999977 2.7755575615628914e-17 0.0" rpy="-1.5707963267948966 -1.5707963267948966 0.0" />
<geometry>
<mesh filename="./lsa1.1_new//meshes/urdf/obj_combined_hulls/right_index_finger_mcp_flexion_link.obj" />
</geometry>
</visual>
<collision>
<origin xyz="-0.004999999999999977 2.7755575615628914e-17 0.0" rpy="-1.5707963267948966 -1.5707963267948966 0.0" />
<geometry>
<mesh filename="./lsa1.1_new//meshes/urdf/obj_combined_hulls/right_index_finger_mcp_flexion_link.obj" />
</geometry>
</collision>
<inertial>
<origin xyz="-0.004711241977214653 0.0026324339410568626 -0.00010618381221107509" rpy="0 0 0" />
<mass value="0.008551500024267173" />
<inertia ixx="4.4703652121635253e-07" ixy="-7.39978996372676e-10" ixz="-2.622286703741456e-10" iyy="4.899247390003298e-07" iyz="-2.389071697354032e-09" izz="2.833370437831568e-07" />
</inertial>
</link>

<joint name="right_index_finger_mcp_flexion" type="revolute">
<origin xyz="-1.2690196116160735e-13 -2.7755575615628914e-17 0.0" rpy="1.5707963267948966 9.163658144169577e-14 1.5707963267948966" />
<parent link="right_index_finger_mcp_abduction_link" />
<child link="right_index_finger_mcp_flexion_link" />
<axis xyz="2.060141577812505e-28 -8.841321559819873e-26 1.0" />
<limit effort="30" velocity="30" lower="-0.2617993877991494" upper="0.7853981633974483" />

</joint>

<link name="right_ring_finger_mcp_flexion_link">
<visual>
<origin xyz="-0.0050000000000000044 0.0 6.938893903907228e-18" rpy="-1.5707963267948966 -1.5707963267948966 0.0" />
<geometry>
<mesh filename="./lsa1.1_new//meshes/urdf/obj_combined_hulls/right_ring_finger_mcp_flexion_link.obj" />
</geometry>
</visual>
<collision>
<origin xyz="-0.0050000000000000044 0.0 6.938893903907228e-18" rpy="-1.5707963267948966 -1.5707963267948966 0.0" />
<geometry>
<mesh filename="./lsa1.1_new//meshes/urdf/obj_combined_hulls/right_ring_finger_mcp_flexion_link.obj" />
</geometry>
</collision>
<inertial>
<origin xyz="-0.004711241977214687 0.002632433941056843 -0.00010618381221108167" rpy="0 0 0" />
<mass value="0.008551500024267173" />
<inertia ixx="4.4703652121634756e-07" ixy="-7.399789963726768e-10" ixz="-2.62228670372992e-10" iyy="4.899247390003302e-07" iyz="-2.3890716973551144e-09" izz="2.833370437831566e-07" />
</inertial>
</link>

<joint name="right_ring_finger_mcp_flexion" type="revolute">
<origin xyz="-1.269123695024632e-13 -5.551115123125783e-17 0.0" rpy="1.5707963267948966 9.163658144170457e-14 1.5707963267948966" />
<parent link="right_ring_finger_mcp_abduction_link" />
<child link="right_ring_finger_mcp_flexion_link" />
<axis xyz="3.322486259379217e-27 -3.2562488430813894e-27 1.0" />
<limit effort="30" velocity="30" lower="-0.2617993877991494" upper="0.7853981633974483" />

</joint>

<link name="right_thumb_opposition_2_link">
<visual>
<origin xyz="0.0 -0.009999999999999981 0.0025000000000000577" rpy="1.5707963267948966 -1.7924713140128638e-29 -6.282435349965838e-30" />
<geometry>
<mesh filename="./lsa1.1_new//meshes/urdf/obj_combined_hulls/right_thumb_opposition_2_link.obj" />
</geometry>
</visual>
<collision>
<origin xyz="0.0 -0.009999999999999981 0.0025000000000000577" rpy="1.5707963267948966 -1.7924713140128638e-29 -6.282435349965838e-30" />
<geometry>
<mesh filename="./lsa1.1_new//meshes/urdf/obj_combined_hulls/right_thumb_opposition_2_link.obj" />
</geometry>
</collision>
<inertial>
<origin xyz="0.00038774005228614647 -0.0013445480356909627 0.005299531345519292" rpy="0 0 0" />
<mass value="0.008439884736772225" />
<inertia ixx="2.921204060469922e-07" ixy="2.3644804522092664e-08" ixz="-4.163538161777446e-09" iyy="2.436578376091954e-07" iyz="3.783541014096465e-08" izz="1.7780986735671503e-07" />
</inertial>
</link>

<joint name="right_thumb_opposition_2" type="continuous">
<origin xyz="1.3877787807814457e-16 0.010000000000000002 0.0" rpy="-3.1415926535897927 -1.4406711147935642e-27 1.852293190682536e-15" />
<parent link="right_thumb_opposition_link" />
<child link="right_thumb_opposition_2_link" />
<axis xyz="1.5325376511644032e-27 -5.551115123096601e-16 0.9999999999999998" />
<mimic joint="right_thumb_opposition" multiplier="-1.0" offset="0" />
<limit effort="30" velocity="30" />

</joint>

<link name="left_thumb_opposition_2_link">
<visual>
<origin xyz="0.0 -0.00999999999999998 0.00250000000000003" rpy="1.5707963267948966 3.038715138805295e-30 7.001191795667485e-30" />
<geometry>
<mesh filename="./lsa1.1_new//meshes/urdf/obj_combined_hulls/left_thumb_opposition_2_link.obj" />
</geometry>
</visual>
<collision>
<origin xyz="0.0 -0.00999999999999998 0.00250000000000003" rpy="1.5707963267948966 3.038715138805295e-30 7.001191795667485e-30" />
<geometry>
<mesh filename="./lsa1.1_new//meshes/urdf/obj_combined_hulls/left_thumb_opposition_2_link.obj" />
</geometry>
</collision>
<inertial>
<origin xyz="-0.0003868602581577054 -0.0013445590103030344 0.005299531719411975" rpy="0 0 0" />
<mass value="0.00843985155793267" />
<inertia ixx="2.9211912919336837e-07" ixy="-2.3654883958273058e-08" ixz="4.169440064085413e-09" iyy="2.4366285897938835e-07" iyz="3.783520433262168e-08" izz="1.7781465501626327e-07" />
</inertial>
</link>

<joint name="left_thumb_opposition_2" type="continuous">
<origin xyz="0.0 0.010000000000000037 2.7755575615628914e-17" rpy="3.1415926535897896 -1.920364695650018e-15 -1.9258075659001609e-16" />
<parent link="left_thumb_opposition_link" />
<child link="left_thumb_opposition_2_link" />
<axis xyz="1.9203646956500003e-15 3.872830714197175e-15 0.9999999999999997" />
<mimic joint="left_thumb_opposition" multiplier="-1.0" offset="0" />
<limit effort="30" velocity="30" />

</joint>

<link name="left_middle_finger_mcp_flexion_link">
<visual>
<origin xyz="-0.004999999999999949 0.0 0.0" rpy="-1.5707963267948966 -1.5707963267948966 0.0" />
<geometry>
<mesh filename="./lsa1.1_new//meshes/urdf/obj_combined_hulls/left_middle_finger_mcp_flexion_link.obj" />
</geometry>
</visual>
<collision>
<origin xyz="-0.004999999999999949 0.0 0.0" rpy="-1.5707963267948966 -1.5707963267948966 0.0" />
<geometry>
<mesh filename="./lsa1.1_new//meshes/urdf/obj_combined_hulls/left_middle_finger_mcp_flexion_link.obj" />
</geometry>
</collision>
<inertial>
<origin xyz="-0.004711241977214631 0.0026324339410568384 -0.00010618381221108103" rpy="0 0 0" />
<mass value="0.008551500024267173" />
<inertia ixx="4.470365212163508e-07" ixy="-7.399789963728613e-10" ixz="-2.6222867037350963e-10" iyy="4.899247390003296e-07" iyz="-2.3890716973544175e-09" izz="2.833370437831563e-07" />
</inertial>
</link>

<joint name="left_middle_finger_mcp_flexion" type="revolute">
<origin xyz="-5.838385330747542e-14 -2.7755575615628914e-17 -2.7755575615628914e-17" rpy="1.5707963267948966 4.795935670845869e-14 1.5707963267948966" />
<parent link="left_middle_finger_mcp_abduction_link" />
<child link="left_middle_finger_mcp_flexion_link" />
<axis xyz="-4.9533721378789184e-24 5.884755090604047e-24 1.0000000000000004" />
<limit effort="30" velocity="30" lower="-0.2617993877991494" upper="0.7853981633974483" />

</joint>

<link name="left_pinkie_finger_mcp_flexion_link">
<visual>
<origin xyz="-0.004999999999999977 0.0 0.0" rpy="-1.5707963267948966 -1.5707963267948966 0.0" />
<geometry>
<mesh filename="./lsa1.1_new//meshes/urdf/obj_combined_hulls/left_pinkie_finger_mcp_flexion_link.obj" />
</geometry>
</visual>
<collision>
<origin xyz="-0.004999999999999977 0.0 0.0" rpy="-1.5707963267948966 -1.5707963267948966 0.0" />
<geometry>
<mesh filename="./lsa1.1_new//meshes/urdf/obj_combined_hulls/left_pinkie_finger_mcp_flexion_link.obj" />
</geometry>
</collision>
<inertial>
<origin xyz="-0.004711241977214655 0.002632433941056829 -0.00010618381221107514" rpy="0 0 0" />
<mass value="0.008551500024267173" />
<inertia ixx="4.470365212163511e-07" ixy="-7.399789963728304e-10" ixz="-2.622286703737048e-10" iyy="4.899247390003303e-07" iyz="-2.389071697354349e-09" izz="2.833370437831571e-07" />
</inertial>
</link>

<joint name="left_pinkie_finger_mcp_flexion" type="revolute">
<origin xyz="-5.809241976351132e-14 -2.7755575615628914e-17 -2.7755575615628914e-17" rpy="1.5707963267948966 4.646331324985575e-14 1.5707963267948966" />
<parent link="left_pinkie_finger_mcp_abduction_link" />
<child link="left_pinkie_finger_mcp_flexion_link" />
<axis xyz="-1.6479090293954654e-16 7.300043886039135e-24 1.00000000000002" />
<limit effort="30" velocity="30" lower="-0.2617993877991494" upper="0.7853981633974483" />

</joint>

<link name="left_index_finger_mcp_flexion_link">
<visual>
<origin xyz="-0.0050000000000000044 0.0 0.0" rpy="-1.5707963267948966 -1.5707963267948966 0.0" />
<geometry>
<mesh filename="./lsa1.1_new//meshes/urdf/obj_combined_hulls/left_index_finger_mcp_flexion_link.obj" />
</geometry>
</visual>
<collision>
<origin xyz="-0.0050000000000000044 0.0 0.0" rpy="-1.5707963267948966 -1.5707963267948966 0.0" />
<geometry>
<mesh filename="./lsa1.1_new//meshes/urdf/obj_combined_hulls/left_index_finger_mcp_flexion_link.obj" />
</geometry>
</collision>
<inertial>
<origin xyz="-0.004711241977214677 0.0026324339410568292 -0.00010618381221106747" rpy="0 0 0" />
<mass value="0.008551500024267173" />
<inertia ixx="4.470365212163518e-07" ixy="-7.399789963728053e-10" ixz="-2.622286703741517e-10" iyy="4.899247390003314e-07" iyz="-2.3890716973541127e-09" izz="2.8333704378315715e-07" />
</inertial>
</link>

<joint name="left_index_finger_mcp_flexion" type="revolute">
<origin xyz="-5.819650317206992e-14 -8.326672684688674e-17 2.7755575615628914e-17" rpy="1.5707963267948966 4.646331324985669e-14 1.5707963267948966" />
<parent link="left_index_finger_mcp_abduction_link" />
<child link="left_index_finger_mcp_flexion_link" />
<axis xyz="-6.62715655053132e-24 1.4830890919149457e-23 0.9999999999999997" />
<limit effort="30" velocity="30" lower="-0.2617993877991494" upper="0.7853981633974483" />

</joint>

<link name="left_ring_finger_mcp_flexion_link">
<visual>
<origin xyz="-0.0050000000000000044 0.0 -6.938893903907228e-18" rpy="-1.5707963267948966 -1.5707963267948966 0.0" />
<geometry>
<mesh filename="./lsa1.1_new//meshes/urdf/obj_combined_hulls/left_ring_finger_mcp_flexion_link.obj" />
</geometry>
</visual>
<collision>
<origin xyz="-0.0050000000000000044 0.0 -6.938893903907228e-18" rpy="-1.5707963267948966 -1.5707963267948966 0.0" />
<geometry>
<mesh filename="./lsa1.1_new//meshes/urdf/obj_combined_hulls/left_ring_finger_mcp_flexion_link.obj" />
</geometry>
</collision>
<inertial>
<origin xyz="-0.004711241977214683 0.0026324339410568457 -0.00010618381221104233" rpy="0 0 0" />
<mass value="0.008551500024267173" />
<inertia ixx="4.470365212163523e-07" ixy="-7.399789963726178e-10" ixz="-2.6222867037318807e-10" iyy="4.899247390003336e-07" iyz="-2.3890716973534845e-09" izz="2.8333704378315736e-07" />
</inertial>
</link>

<joint name="left_ring_finger_mcp_flexion" type="revolute">
<origin xyz="-5.825201432330118e-14 1.0547118733938987e-15 -2.7755575615628914e-17" rpy="1.5707963267948961 4.646331324985528e-14 1.570796326794896" />
<parent link="left_ring_finger_mcp_abduction_link" />
<child link="left_ring_finger_mcp_flexion_link" />
<axis xyz="-7.754116124302729e-16 6.586411158873311e-24 1.0000000000000284" />
<limit effort="30" velocity="30" lower="-0.2617993877991494" upper="0.7853981633974483" />

</joint>

<link name="right_middle_finger_mcp_flexion_2_link">
<visual>
<origin xyz="0.0050000000000000044 0.0 0.0" rpy="-1.5707963267948966 -1.5707963267948966 0.0" />
<geometry>
<mesh filename="./lsa1.1_new//meshes/urdf/obj_combined_hulls/right_middle_finger_mcp_flexion_2_link.obj" />
</geometry>
</visual>
<collision>
<origin xyz="0.0050000000000000044 0.0 0.0" rpy="-1.5707963267948966 -1.5707963267948966 0.0" />
<geometry>
<mesh filename="./lsa1.1_new//meshes/urdf/obj_combined_hulls/right_middle_finger_mcp_flexion_2_link.obj" />
</geometry>
</collision>
<inertial>
<origin xyz="-0.017753106114925206 0.0006974648535870624 -1.4930446210341499e-05" rpy="0 0 0" />
<mass value="0.028663232704364102" />
<inertia ixx="7.506214439170214e-07" ixy="-9.690782029879847e-08" ixz="-1.334994622456006e-09" iyy="5.0795461463279e-06" iyz="-9.092917988747228e-10" izz="5.09042878404653e-06" />
</inertial>
</link>

<joint name="right_middle_finger_mcp_flexion_2" type="continuous">
<origin xyz="-0.010000000000000009 2.7755575615628914e-17 1.2704420848663744e-13" rpy="-2.629064860400033e-25 -5.808777275594922e-27 -8.512891816585116e-14" />
<parent link="right_middle_finger_mcp_flexion_link" />
<child link="right_middle_finger_mcp_flexion_2_link" />
<axis xyz="-5.808759707924014e-27 2.629134936432474e-25 1.0" />
<mimic joint="right_middle_finger_mcp_flexion" multiplier="1.0" offset="0" />
<limit effort="30" velocity="30" />

</joint>

<link name="right_pinkie_finger_mcp_flexion_2_link">
<visual>
<origin xyz="0.0050000000000000044 -2.7755575615628914e-17 0.0" rpy="-1.5707963267948966 -1.5707963267948966 0.0" />
<geometry>
<mesh filename="./lsa1.1_new//meshes/urdf/obj_combined_hulls/right_pinkie_finger_mcp_flexion_2_link.obj" />
</geometry>
</visual>
<collision>
<origin xyz="0.0050000000000000044 -2.7755575615628914e-17 0.0" rpy="-1.5707963267948966 -1.5707963267948966 0.0" />
<geometry>
<mesh filename="./lsa1.1_new//meshes/urdf/obj_combined_hulls/right_pinkie_finger_mcp_flexion_2_link.obj" />
</geometry>
</collision>
<inertial>
<origin xyz="-0.01775310611492513 0.0006974648535870166 -1.4930446210272529e-05" rpy="0 0 0" />
<mass value="0.028663232704364102" />
<inertia ixx="7.506214439170196e-07" ixy="-9.690782029880759e-08" ixz="-1.3349946224639048e-09" iyy="5.079546146327878e-06" iyz="-9.092917988761157e-10" izz="5.090428784046508e-06" />
</inertial>
</link>

<joint name="right_pinkie_finger_mcp_flexion_2" type="continuous">
<origin xyz="-0.009999999999999981 0.0 1.267180804731538e-13" rpy="-1.371007635183962e-27 -5.6933306144986086e-27 -8.512891816585538e-14" />
<parent link="right_pinkie_finger_mcp_flexion_link" />
<child link="right_pinkie_finger_mcp_flexion_2_link" />
<axis xyz="-5.691509969651035e-27 1.3742573892796945e-27 1.0" />
<mimic joint="right_pinkie_finger_mcp_flexion" multiplier="1.0" offset="0" />
<limit effort="30" velocity="30" />

</joint>

<link name="right_index_finger_mcp_flexion_2_link">
<visual>
<origin xyz="0.004999999999999977 0.0 0.0" rpy="-1.5707963267948966 -1.5707963267948966 0.0" />
<geometry>
<mesh filename="./lsa1.1_new//meshes/urdf/obj_combined_hulls/right_index_finger_mcp_flexion_2_link.obj" />
</geometry>
</visual>
<collision>
<origin xyz="0.004999999999999977 0.0 0.0" rpy="-1.5707963267948966 -1.5707963267948966 0.0" />
<geometry>
<mesh filename="./lsa1.1_new//meshes/urdf/obj_combined_hulls/right_index_finger_mcp_flexion_2_link.obj" />
</geometry>
</collision>
<inertial>
<origin xyz="-0.017753106114925105 0.0006974648535870317 -1.4930446210353203e-05" rpy="0 0 0" />
<mass value="0.028663232704364102" />
<inertia ixx="7.506214439170126e-07" ixy="-9.690782029880812e-08" ixz="-1.3349946224640553e-09" iyy="5.0795461463278675e-06" iyz="-9.092917988723148e-10" izz="5.090428784046508e-06" />
</inertial>
</link>

<joint name="right_index_finger_mcp_flexion_2" type="continuous">
<origin xyz="-0.009999999999999981 5.551115123125783e-17 1.268984917146554e-13" rpy="1.251359558100394e-26 -5.765905817778942e-27 1.2195827499338784e-14" />
<parent link="right_index_finger_mcp_flexion_link" />
<child link="right_index_finger_mcp_flexion_2_link" />
<axis xyz="-5.764085172931368e-27 -1.2506640681169203e-26 1.0" />
<mimic joint="right_index_finger_mcp_flexion" multiplier="1.0" offset="0" />
<limit effort="30" velocity="30" />

</joint>

<link name="right_ring_finger_mcp_flexion_2_link">
<visual>
<origin xyz="0.0050000000000000044 2.7755575615628914e-17 0.0" rpy="-1.5707963267948966 -1.5707963267948966 0.0" />
<geometry>
<mesh filename="./lsa1.1_new//meshes/urdf/obj_combined_hulls/right_ring_finger_mcp_flexion_2_link.obj" />
</geometry>
</visual>
<collision>
<origin xyz="0.0050000000000000044 2.7755575615628914e-17 0.0" rpy="-1.5707963267948966 -1.5707963267948966 0.0" />
<geometry>
<mesh filename="./lsa1.1_new//meshes/urdf/obj_combined_hulls/right_ring_finger_mcp_flexion_2_link.obj" />
</geometry>
</collision>
<inertial>
<origin xyz="-0.01775310611492491 0.0006974648535867941 -1.4930446210123485e-05" rpy="0 0 0" />
<mass value="0.028663232704364102" />
<inertia ixx="7.506214439170268e-07" ixy="-9.690782029885475e-08" ixz="-1.334994622464231e-09" iyy="5.079546146327864e-06" iyz="-9.092917988594362e-10" izz="5.0904287840464706e-06" />
</inertial>
</link>

<joint name="right_ring_finger_mcp_flexion_2" type="continuous">
<origin xyz="-0.010000000000000037 2.7755575615628914e-17 1.2612133559741778e-13" rpy="-1.6653345395208024e-16 1.6653345369038017e-16 1.219582749934419e-14" />
<parent link="right_ring_finger_mcp_flexion_link" />
<child link="right_ring_finger_mcp_flexion_2_link" />
<axis xyz="1.6653345369039575e-16 1.6653345395208404e-16 0.9999999999999998" />
<mimic joint="right_ring_finger_mcp_flexion" multiplier="1.0" offset="0" />
<limit effort="30" velocity="30" />

</joint>

<link name="right_thumb_abduction_link">
<visual>
<origin xyz="0.0 -2.7755575615628914e-17 -0.005999999999999983" rpy="2.408554367752176 -1.6185429562719805e-30 -5.530012156504861e-30" />
<geometry>
<mesh filename="./lsa1.1_new//meshes/urdf/obj_combined_hulls/right_thumb_abduction_link.obj" />
</geometry>
</visual>
<collision>
<origin xyz="0.0 -2.7755575615628914e-17 -0.005999999999999983" rpy="2.408554367752176 -1.6185429562719805e-30 -5.530012156504861e-30" />
<geometry>
<mesh filename="./lsa1.1_new//meshes/urdf/obj_combined_hulls/right_thumb_abduction_link.obj" />
</geometry>
</collision>
<inertial>
<origin xyz="0.0010911350554360503 0.003234398213359862 -0.00775714558371247" rpy="0 0 0" />
<mass value="0.012765482752373875" />
<inertia ixx="5.78916421332262e-07" ixy="1.25732123213309e-08" ixz="-2.6286397920908605e-09" iyy="4.1722746386258616e-07" iyz="1.204110056321561e-07" izz="3.369189516118902e-07" />
</inertial>
</link>

<joint name="right_thumb_abduction" type="revolute">
<origin xyz="0.0 -0.004 0.00250000000000003" rpy="-1.5707963267948999 -1.7924713140025074e-29 -2.0258739518743e-29" />
<parent link="right_thumb_opposition_2_link" />
<child link="right_thumb_abduction_link" />
<axis xyz="1.5594847125043714e-29 -1.379523666507455e-14 1.0000000000000093" />
<limit effort="30" velocity="30" lower="-1.0471975511965976" upper="0" />

</joint>

<link name="left_thumb_abduction_link">
<visual>
<origin xyz="0.0 -2.7755575615628914e-17 -0.0059999999999999845" rpy="2.408554367752176 -2.009157007409366e-29 3.786532345060856e-29" />
<geometry>
<mesh filename="./lsa1.1_new//meshes/urdf/obj_combined_hulls/left_thumb_abduction_link.obj" />
</geometry>
</visual>
<collision>
<origin xyz="0.0 -2.7755575615628914e-17 -0.0059999999999999845" rpy="2.408554367752176 -2.009157007409366e-29 3.786532345060856e-29" />
<geometry>
<mesh filename="./lsa1.1_new//meshes/urdf/obj_combined_hulls/left_thumb_abduction_link.obj" />
</geometry>
</collision>
<inertial>
<origin xyz="-0.0010908578141504636 0.0032343857175785545 -0.007757141921007659" rpy="0 0 0" />
<mass value="0.0127654939716413" />
<inertia ixx="5.789164100978102e-07" ixy="-1.2562932149633889e-08" ixz="2.5840967157659508e-09" iyy="4.1723517232310925e-07" iyz="1.2041080829750034e-07" izz="3.369277600845335e-07" />
</inertial>
</link>

<joint name="left_thumb_abduction" type="revolute">
<origin xyz="-2.7755575615628914e-17 -0.003999999999999997 0.0025000000000000022" rpy="-1.570796326794894 -1.2246468349439602e-16 -5.655856219325425e-29" />
<parent link="left_thumb_opposition_2_link" />
<child link="left_thumb_abduction_link" />
<axis xyz="8.326869437131315e-29 -3.1244082964614943e-15 1.0000000000000202" />
<limit effort="30" velocity="30" lower="0" upper="1.0471975511965976" />

</joint>

<link name="left_middle_finger_mcp_flexion_2_link">
<visual>
<origin xyz="0.0050000000000000044 0.0 0.0" rpy="-1.5707963267948966 -1.5707963267948966 0.0" />
<geometry>
<mesh filename="./lsa1.1_new//meshes/urdf/obj_combined_hulls/left_middle_finger_mcp_flexion_2_link.obj" />
</geometry>
</visual>
<collision>
<origin xyz="0.0050000000000000044 0.0 0.0" rpy="-1.5707963267948966 -1.5707963267948966 0.0" />
<geometry>
<mesh filename="./lsa1.1_new//meshes/urdf/obj_combined_hulls/left_middle_finger_mcp_flexion_2_link.obj" />
</geometry>
</collision>
<inertial>
<origin xyz="-0.017753106114925067 0.0006974648535870728 -1.4930446195195225e-05" rpy="0 0 0" />
<mass value="0.028663232704364102" />
<inertia ixx="7.506214439170263e-07" ixy="-9.690782029880476e-08" ixz="-1.3349946236882504e-09" iyy="5.079546146327872e-06" iyz="-9.092917997200197e-10" izz="5.090428784046496e-06" />
</inertial>
</link>

<joint name="left_middle_finger_mcp_flexion_2" type="continuous">
<origin xyz="-0.009999999999999953 0.0 5.837691441357151e-14" rpy="-3.6505082826698446e-24 -6.123233767588625e-17 4.6948446559022545e-14" />
<parent link="left_middle_finger_mcp_flexion_link" />
<child link="left_middle_finger_mcp_flexion_2_link" />
<axis xyz="-6.123233767588624e-17 3.650511843074102e-24 0.9999999999999992" />
<mimic joint="left_middle_finger_mcp_flexion" multiplier="1.0" offset="0" />
<limit effort="30" velocity="30" />

</joint>

<link name="left_pinkie_finger_mcp_flexion_2_link">
<visual>
<origin xyz="0.005000000000000032 -2.7755575615628914e-17 -1.3877787807814457e-17" rpy="-1.5707963267948966 -1.5707963267948966 0.0" />
<geometry>
<mesh filename="./lsa1.1_new//meshes/urdf/obj_combined_hulls/left_pinkie_finger_mcp_flexion_2_link.obj" />
</geometry>
</visual>
<collision>
<origin xyz="0.005000000000000032 -2.7755575615628914e-17 -1.3877787807814457e-17" rpy="-1.5707963267948966 -1.5707963267948966 0.0" />
<geometry>
<mesh filename="./lsa1.1_new//meshes/urdf/obj_combined_hulls/left_pinkie_finger_mcp_flexion_2_link.obj" />
</geometry>
</collision>
<inertial>
<origin xyz="-0.017753106114925123 0.0006974648535870242 -1.4930446195108968e-05" rpy="0 0 0" />
<mass value="0.028663232704364102" />
<inertia ixx="7.506214439170323e-07" ixy="-9.690782029879777e-08" ixz="-1.3349946236969674e-09" iyy="5.07954614632797e-06" iyz="-9.092917997223176e-10" izz="5.090428784046564e-06" />
</inertial>
</link>

<joint name="left_pinkie_finger_mcp_flexion_2" type="continuous">
<origin xyz="-0.009999999999999981 0.0 5.809241976351132e-14" rpy="1.016033814377578e-16 2.2602324111072713e-16 4.646331324977308e-14" />
<parent link="left_pinkie_finger_mcp_flexion_link" />
<child link="left_pinkie_finger_mcp_flexion_2_link" />
<axis xyz="2.260232410913037e-16 -1.016033814377584e-16 1.0" />
<mimic joint="left_pinkie_finger_mcp_flexion" multiplier="1.0" offset="0" />
<limit effort="30" velocity="30" />

</joint>

<link name="left_index_finger_mcp_flexion_2_link">
<visual>
<origin xyz="0.0050000000000000044 -5.551115123125783e-17 -3.469446951953614e-18" rpy="-1.5707963267948966 -1.5707963267948966 0.0" />
<geometry>
<mesh filename="./lsa1.1_new//meshes/urdf/obj_combined_hulls/left_index_finger_mcp_flexion_2_link.obj" />
</geometry>
</visual>
<collision>
<origin xyz="0.0050000000000000044 -5.551115123125783e-17 -3.469446951953614e-18" rpy="-1.5707963267948966 -1.5707963267948966 0.0" />
<geometry>
<mesh filename="./lsa1.1_new//meshes/urdf/obj_combined_hulls/left_index_finger_mcp_flexion_2_link.obj" />
</geometry>
</collision>
<inertial>
<origin xyz="-0.01775310611492508 0.000697464853587014 -1.4930446195198618e-05" rpy="0 0 0" />
<mass value="0.028663232704364102" />
<inertia ixx="7.506214439170216e-07" ixy="-9.690782029880669e-08" ixz="-1.3349946236910686e-09" iyy="5.079546146327866e-06" iyz="-9.092917997206252e-10" izz="5.0904287840465045e-06" />
</inertial>
</link>

<joint name="left_index_finger_mcp_flexion_2" type="continuous">
<origin xyz="-0.010000000000000009 -2.7755575615628914e-17 5.821731985378165e-14" rpy="1.3268549661479943e-15 -5.686432309228694e-16 4.694844655902256e-14" />
<parent link="left_index_finger_mcp_flexion_link" />
<child link="left_index_finger_mcp_flexion_2_link" />
<axis xyz="-5.686432309034461e-16 -1.32685496614801e-15 1.0" />
<mimic joint="left_index_finger_mcp_flexion" multiplier="1.0" offset="0" />
<limit effort="30" velocity="30" />

</joint>

<link name="left_ring_finger_mcp_flexion_2_link">
<visual>
<origin xyz="0.0050000000000000044 0.0 0.0" rpy="-1.5707963267948966 -1.5707963267948966 0.0" />
<geometry>
<mesh filename="./lsa1.1_new//meshes/urdf/obj_combined_hulls/left_ring_finger_mcp_flexion_2_link.obj" />
</geometry>
</visual>
<collision>
<origin xyz="0.0050000000000000044 0.0 0.0" rpy="-1.5707963267948966 -1.5707963267948966 0.0" />
<geometry>
<mesh filename="./lsa1.1_new//meshes/urdf/obj_combined_hulls/left_ring_finger_mcp_flexion_2_link.obj" />
</geometry>
</collision>
<inertial>
<origin xyz="-0.017753106114924998 0.00069746485358716 -1.4930446195059087e-05" rpy="0 0 0" />
<mass value="0.028663232704364102" />
<inertia ixx="7.506214439170473e-07" ixy="-9.690782029879333e-08" ixz="-1.3349946236854905e-09" iyy="5.079546146327896e-06" iyz="-9.092917997292435e-10" izz="5.090428784046502e-06" />
</inertial>
</link>

<joint name="left_ring_finger_mcp_flexion_2" type="continuous">
<origin xyz="-0.010000000000000009 0.0 5.820344206597383e-14" rpy="1.261925670429066e-15 1.263567642625866e-15 4.334382635048975e-14" />
<parent link="left_ring_finger_mcp_flexion_link" />
<child link="left_ring_finger_mcp_flexion_2_link" />
<axis xyz="1.263567642625866e-15 -1.2619256704290226e-15 1.0" />
<mimic joint="left_ring_finger_mcp_flexion" multiplier="1.0" offset="0" />
<limit effort="30" velocity="30" />

</joint>

<link name="right_middle_finger_pip_link">
<visual>
<origin xyz="0.043499999999999955 2.7755575615628914e-17 6.938893903907228e-18" rpy="-1.5707963267948966 -1.5707963267948966 0.0" />
<geometry>
<mesh filename="./lsa1.1_new//meshes/urdf/obj_combined_hulls/right_middle_finger_pip_link.obj" />
</geometry>
</visual>
<collision>
<origin xyz="0.043499999999999955 2.7755575615628914e-17 6.938893903907228e-18" rpy="-1.5707963267948966 -1.5707963267948966 0.0" />
<geometry>
<mesh filename="./lsa1.1_new//meshes/urdf/obj_combined_hulls/right_middle_finger_pip_link.obj" />
</geometry>
</collision>
<inertial>
<origin xyz="-0.002984789265693259 0.00016924584932460421 -3.5854567703969945e-06" rpy="0 0 0" />
<mass value="0.001355945340955129" />
<inertia ixx="6.243282502825332e-09" ixy="-1.882376880637704e-09" ixz="-2.845186413578763e-12" iyy="1.608764762340794e-08" iyz="-1.3567055754999399e-12" izz="1.444166351497804e-08" />
</inertial>
</link>

<joint name="right_middle_finger_pip" type="revolute">
<origin xyz="-0.03849999999999995 -2.7755575615628914e-17 -1.345867861601846e-13" rpy="9.658940314229847e-15 1.6566130150647106e-14 -1.6492728788773517e-14" />
<parent link="right_middle_finger_mcp_flexion_2_link" />
<child link="right_middle_finger_pip_link" />
<axis xyz="1.65661301506468e-14 -9.658940314230106e-15 0.9999999999999911" />
<limit effort="30" velocity="30" lower="0" upper="0.9599310885968813" />

</joint>

<link name="right_pinkie_finger_pip_link">
<visual>
<origin xyz="0.043499999999999955 -2.7755575615628914e-17 1.3877787807814457e-17" rpy="-1.5707963267948966 -1.5707963267948966 0.0" />
<geometry>
<mesh filename="./lsa1.1_new//meshes/urdf/obj_combined_hulls/right_pinkie_finger_pip_link.obj" />
</geometry>
</visual>
<collision>
<origin xyz="0.043499999999999955 -2.7755575615628914e-17 1.3877787807814457e-17" rpy="-1.5707963267948966 -1.5707963267948966 0.0" />
<geometry>
<mesh filename="./lsa1.1_new//meshes/urdf/obj_combined_hulls/right_pinkie_finger_pip_link.obj" />
</geometry>
</collision>
<inertial>
<origin xyz="-0.002984789265693265 0.0001692458493245501 -3.5854567703917133e-06" rpy="0 0 0" />
<mass value="0.001355945340955129" />
<inertia ixx="6.243282502825544e-09" ixy="-1.882376880637713e-09" ixz="-2.8451864136236036e-12" iyy="1.6087647623407906e-08" iyz="-1.3567055754796713e-12" izz="1.4441663514978044e-08" />
</inertial>
</link>

<joint name="right_pinkie_finger_pip" type="revolute">
<origin xyz="-0.03849999999999995 -2.7755575615628914e-17 -1.315197950546576e-13" rpy="3.4036159478568794e-28 -4.489833165893209e-28 -6.609601055202351e-15" />
<parent link="right_pinkie_finger_mcp_flexion_2_link" />
<child link="right_pinkie_finger_pip_link" />
<axis xyz="-4.471626717417486e-28 -3.360221275329671e-28 1.0" />
<limit effort="30" velocity="30" lower="0" upper="0.9599310885968813" />

</joint>

<link name="right_index_finger_pip_link">
<visual>
<origin xyz="0.043499999999999955 0.0 -3.469446951953614e-18" rpy="-1.5707963267948966 -1.5707963267948966 0.0" />
<geometry>
<mesh filename="./lsa1.1_new//meshes/urdf/obj_combined_hulls/right_index_finger_pip_link.obj" />
</geometry>
</visual>
<collision>
<origin xyz="0.043499999999999955 0.0 -3.469446951953614e-18" rpy="-1.5707963267948966 -1.5707963267948966 0.0" />
<geometry>
<mesh filename="./lsa1.1_new//meshes/urdf/obj_combined_hulls/right_index_finger_pip_link.obj" />
</geometry>
</collision>
<inertial>
<origin xyz="-0.002984789265693266 0.00016924584932457692 -3.585456770407781e-06" rpy="0 0 0" />
<mass value="0.001355945340955129" />
<inertia ixx="6.24328250282555e-09" ixy="-1.882376880637717e-09" ixz="-2.845186413617323e-12" iyy="1.608764762340791e-08" iyz="-1.356705575478697e-12" izz="1.4441663514978052e-08" />
</inertial>
</link>

<joint name="right_index_finger_pip" type="revolute">
<origin xyz="-0.03849999999999998 0.0 -1.3172102297787092e-13" rpy="-1.328919069914834e-26 2.010380693127929e-28 -1.2195827499324847e-14" />
<parent link="right_index_finger_mcp_flexion_2_link" />
<child link="right_index_finger_pip_link" />
<axis xyz="2.028587141603652e-28 1.329614559898412e-26 1.0" />
<limit effort="30" velocity="30" lower="0" upper="0.9599310885968813" />

</joint>

<link name="right_ring_finger_pip_link">
<visual>
<origin xyz="0.04349999999999993 -2.7755575615628914e-17 -6.938893903907228e-18" rpy="-1.5707963267948966 -1.5707963267948966 0.0" />
<geometry>
<mesh filename="./lsa1.1_new//meshes/urdf/obj_combined_hulls/right_ring_finger_pip_link.obj" />
</geometry>
</visual>
<collision>
<origin xyz="0.04349999999999993 -2.7755575615628914e-17 -6.938893903907228e-18" rpy="-1.5707963267948966 -1.5707963267948966 0.0" />
<geometry>
<mesh filename="./lsa1.1_new//meshes/urdf/obj_combined_hulls/right_ring_finger_pip_link.obj" />
</geometry>
</collision>
<inertial>
<origin xyz="-0.0029847892656932875 0.0001692458493245524 -3.5854567704100934e-06" rpy="0 0 0" />
<mass value="0.001355945340955129" />
<inertia ixx="6.243282502825547e-09" ixy="-1.8823768806377244e-09" ixz="-2.8451864136184296e-12" iyy="1.6087647623407896e-08" iyz="-1.3567055754777231e-12" izz="1.4441663514978035e-08" />
</inertial>
</link>

<joint name="right_ring_finger_pip" type="revolute">
<origin xyz="-0.03849999999999995 2.7755575615628914e-17 -1.3365697437706103e-13" rpy="-9.60342916300004e-15 -1.6455107848192517e-14 -1.2195827499330374e-14" />
<parent link="right_ring_finger_mcp_flexion_2_link" />
<child link="right_ring_finger_pip_link" />
<axis xyz="-1.6455107848192542e-14 9.60342916300024e-15 1.0000000000000089" />
<limit effort="30" velocity="30" lower="0" upper="0.9599310885968813" />

</joint>

<link name="right_thumb_mcp_flexion_link">
<visual>
<origin xyz="0.010000000000000078 0.0 0.0" rpy="-1.5707963267948966 -1.5707963267948966 0.0" />
<geometry>
<mesh filename="./lsa1.1_new//meshes/urdf/obj_combined_hulls/right_thumb_mcp_flexion_link.obj" />
</geometry>
</visual>
<collision>
<origin xyz="0.010000000000000078 0.0 0.0" rpy="-1.5707963267948966 -1.5707963267948966 0.0" />
<geometry>
<mesh filename="./lsa1.1_new//meshes/urdf/obj_combined_hulls/right_thumb_mcp_flexion_link.obj" />
</geometry>
</collision>
<inertial>
<origin xyz="-0.00597746199289117 0.0003702119471738163 0.0015362490695625653" rpy="0 0 0" />
<mass value="0.006345688475300095" />
<inertia ixx="1.1014718268788303e-07" ixy="4.8656645750806755e-09" ixz="-1.810444931282839e-08" iyy="2.1070524240890932e-07" iyz="-2.7495447673011545e-09" izz="1.4737796264273575e-07" />
</inertial>
</link>

<joint name="right_thumb_mcp_flexion" type="revolute">
<origin xyz="3.3306690738754696e-16 0.007431448254773959 -0.012691306063588592" rpy="-1.5707963267948966 -0.733038285837606 -1.5707963267948692" />
<parent link="right_thumb_abduction_link" />
<child link="right_thumb_mcp_flexion_link" />
<axis xyz="-2.032953842009841e-14 6.9280974042875036e-15 0.9999999999999882" />
<limit effort="30" velocity="30" lower="-0.17453292519943295" upper="0.5235987755982988" />

</joint>

<link name="left_thumb_mcp_flexion_link">
<visual>
<origin xyz="0.01000000000000005 -1.3877787807814457e-17 2.7755575615628914e-17" rpy="-1.5707963267948966 -1.5707963267948966 0.0" />
<geometry>
<mesh filename="./lsa1.1_new//meshes/urdf/obj_combined_hulls/left_thumb_mcp_flexion_link.obj" />
</geometry>
</visual>
<collision>
<origin xyz="0.01000000000000005 -1.3877787807814457e-17 2.7755575615628914e-17" rpy="-1.5707963267948966 -1.5707963267948966 0.0" />
<geometry>
<mesh filename="./lsa1.1_new//meshes/urdf/obj_combined_hulls/left_thumb_mcp_flexion_link.obj" />
</geometry>
</collision>
<inertial>
<origin xyz="-0.005977461992891186 0.0003702118682950721 -0.0015362490695625373" rpy="0 0 0" />
<mass value="0.006345688475300095" />
<inertia ixx="1.1014717911499577e-07" ixy="4.865662213969141e-09" ixz="1.8104449312827868e-08" iyy="2.1070524240889423e-07" iyz="2.7495089900609167e-09" izz="1.4737795906986288e-07" />
</inertial>
</link>

<joint name="left_thumb_mcp_flexion" type="revolute">
<origin xyz="0.0 0.007431448254773959 -0.012691306063588592" rpy="-1.5707963267948966 -0.7330382858376174 -1.570796326794895" />
<parent link="left_thumb_abduction_link" />
<child link="left_thumb_mcp_flexion_link" />
<axis xyz="-1.1312229114718844e-15 -1.1778413540425398e-15 0.9999999999999684" />
<limit effort="30" velocity="30" lower="-0.17453292519943295" upper="0.5235987755982988" />

</joint>

<link name="left_middle_finger_pip_link">
<visual>
<origin xyz="0.043499999999999955 0.0 0.0" rpy="-1.5707963267948966 -1.5707963267948966 0.0" />
<geometry>
<mesh filename="./lsa1.1_new//meshes/urdf/obj_combined_hulls/left_middle_finger_pip_link.obj" />
</geometry>
</visual>
<collision>
<origin xyz="0.043499999999999955 0.0 0.0" rpy="-1.5707963267948966 -1.5707963267948966 0.0" />
<geometry>
<mesh filename="./lsa1.1_new//meshes/urdf/obj_combined_hulls/left_middle_finger_pip_link.obj" />
</geometry>
</collision>
<inertial>
<origin xyz="-0.002984789265693265 0.00016924584932457692 -3.5854567704040613e-06" rpy="0 0 0" />
<mass value="0.001355945340955129" />
<inertia ixx="6.243282502825624e-09" ixy="-1.882376880637707e-09" ixz="-2.8451864136156654e-12" iyy="1.608764762340811e-08" iyz="-1.356705575478932e-12" izz="1.4441663514978052e-08" />
</inertial>
</link>

<joint name="left_middle_finger_pip" type="revolute">
<origin xyz="-0.03849999999999992 0.0 -4.08006961549745e-15" rpy="1.0160337799869147e-16 2.872555837205623e-16 4.485351847000438e-14" />
<parent link="left_middle_finger_mcp_flexion_2_link" />
<child link="left_middle_finger_pip_link" />
<axis xyz="2.8725558373998538e-16 -1.0160337799867426e-16 1.0" />
<limit effort="30" velocity="30" lower="0" upper="0.9599310885968813" />

</joint>

<link name="left_pinkie_finger_pip_link">
<visual>
<origin xyz="0.043499999999999955 0.0 0.0" rpy="-1.5707963267948966 -1.5707963267948966 0.0" />
<geometry>
<mesh filename="./lsa1.1_new//meshes/urdf/obj_combined_hulls/left_pinkie_finger_pip_link.obj" />
</geometry>
</visual>
<collision>
<origin xyz="0.043499999999999955 0.0 0.0" rpy="-1.5707963267948966 -1.5707963267948966 0.0" />
<geometry>
<mesh filename="./lsa1.1_new//meshes/urdf/obj_combined_hulls/left_pinkie_finger_pip_link.obj" />
</geometry>
</collision>
<inertial>
<origin xyz="-0.002984789265693259 0.00016924584932457643 -3.585456770403962e-06" rpy="0 0 0" />
<mass value="0.001355945340955129" />
<inertia ixx="6.2432825028255505e-09" ixy="-1.882376880637714e-09" ixz="-2.8451864136154214e-12" iyy="1.60876476234079e-08" iyz="-1.3567055754785923e-12" izz="1.4441663514978044e-08" />
</inertial>
</link>

<joint name="left_pinkie_finger_pip" type="revolute">
<origin xyz="-0.03849999999999992 -2.7755575615628914e-17 -4.135580766728708e-15" rpy="-3.294032712636351e-24 4.953371975023825e-24 4.350371343661723e-14" />
<parent link="left_pinkie_finger_mcp_flexion_2_link" />
<child link="left_pinkie_finger_pip_link" />
<axis xyz="4.953371975023826e-24 3.294022193180784e-24 0.9999999999999992" />
<limit effort="30" velocity="30" lower="0" upper="0.9599310885968813" />

</joint>

<link name="left_index_finger_pip_link">
<visual>
<origin xyz="0.04349999999999998 -2.7755575615628914e-17 0.0" rpy="-1.5707963267948966 -1.5707963267948966 0.0" />
<geometry>
<mesh filename="./lsa1.1_new//meshes/urdf/obj_combined_hulls/left_index_finger_pip_link.obj" />
</geometry>
</visual>
<collision>
<origin xyz="0.04349999999999998 -2.7755575615628914e-17 0.0" rpy="-1.5707963267948966 -1.5707963267948966 0.0" />
<geometry>
<mesh filename="./lsa1.1_new//meshes/urdf/obj_combined_hulls/left_index_finger_pip_link.obj" />
</geometry>
</collision>
<inertial>
<origin xyz="-0.002984789265693228 0.00016924584932454914 -3.5854567704046576e-06" rpy="0 0 0" />
<mass value="0.001355945340955129" />
<inertia ixx="6.243282502825549e-09" ixy="-1.8823768806377137e-09" ixz="-2.8451864136159707e-12" iyy="1.6087647623407876e-08" iyz="-1.3567055754786866e-12" izz="1.444166351497802e-08" />
</inertial>
</link>

<joint name="left_index_finger_pip" type="revolute">
<origin xyz="-0.03849999999999995 -2.7755575615628914e-17 -4.073130721593543e-15" rpy="-1.735768331483401e-15 1.872345339758885e-15 4.319208884133366e-14" />
<parent link="left_index_finger_mcp_flexion_2_link" />
<child link="left_index_finger_pip_link" />
<axis xyz="1.872345339380119e-15 1.7357683314834195e-15 0.999999999999965" />
<limit effort="30" velocity="30" lower="0" upper="0.9599310885968813" />

</joint>

<link name="left_ring_finger_pip_link">
<visual>
<origin xyz="0.04350000000000001 2.7755575615628914e-17 0.0" rpy="-1.5707963267948966 -1.5707963267948966 0.0" />
<geometry>
<mesh filename="./lsa1.1_new//meshes/urdf/obj_combined_hulls/left_ring_finger_pip_link.obj" />
</geometry>
</visual>
<collision>
<origin xyz="0.04350000000000001 2.7755575615628914e-17 0.0" rpy="-1.5707963267948966 -1.5707963267948966 0.0" />
<geometry>
<mesh filename="./lsa1.1_new//meshes/urdf/obj_combined_hulls/left_ring_finger_pip_link.obj" />
</geometry>
</collision>
<inertial>
<origin xyz="-0.0029847892656931978 0.0001692458493246047 -3.58545677040397e-06" rpy="0 0 0" />
<mass value="0.001355945340955129" />
<inertia ixx="6.243282502825549e-09" ixy="-1.882376880637714e-09" ixz="-2.8451864136154683e-12" iyy="1.6087647623407903e-08" iyz="-1.3567055754786004e-12" izz="1.4441663514978044e-08" />
</inertial>
</link>

<joint name="left_ring_finger_pip" type="revolute">
<origin xyz="-0.03849999999999995 0.0 -4.1772141301521515e-15" rpy="-1.2252515792046691e-15 -9.76312062194603e-16 4.3679368832469915e-14" />
<parent link="left_ring_finger_mcp_flexion_2_link" />
<child link="left_ring_finger_pip_link" />
<axis xyz="-9.763120622043147e-16 1.2252515792046168e-15 1.0000000000000004" />
<limit effort="30" velocity="30" lower="0" upper="0.9599310885968813" />

</joint>

<link name="right_middle_finger_pip_2_link">
<visual>
<origin xyz="0.050499999999999934 -2.7755575615628914e-17 0.0" rpy="-1.5707963267948966 -1.5707963267948966 0.0" />
<geometry>
<mesh filename="./lsa1.1_new//meshes/urdf/obj_combined_hulls/right_middle_finger_pip_2_link.obj" />
</geometry>
</visual>
<collision>
<origin xyz="0.050499999999999934 -2.7755575615628914e-17 0.0" rpy="-1.5707963267948966 -1.5707963267948966 0.0" />
<geometry>
<mesh filename="./lsa1.1_new//meshes/urdf/obj_combined_hulls/right_middle_finger_pip_2_link.obj" />
</geometry>
</collision>
<inertial>
<origin xyz="-0.006998651016719841 -0.0001709021706498025 -4.597237124358995e-06" rpy="0 0 0" />
<mass value="0.008583915368359746" />
<inertia ixx="1.6902733152684897e-07" ixy="1.0810765845647785e-08" ixz="1.6979113593528276e-10" iyy="3.536501590411394e-07" iyz="-2.5145573497517817e-11" izz="3.0354744604926136e-07" />
</inertial>
</link>

<joint name="right_middle_finger_pip_2" type="continuous">
<origin xyz="-0.0069999999999999785 2.7755575615628914e-17 6.938893903907228e-18" rpy="-9.658940314259014e-15 -1.662736249060541e-14 1.702158107079831e-14" />
<parent link="right_middle_finger_pip_link" />
<child link="right_middle_finger_pip_2_link" />
<axis xyz="-1.662736249060572e-14 9.658940314258744e-15 1.0000000000000089" />
<mimic joint="right_middle_finger_pip" multiplier="1.0" offset="0" />
<limit effort="30" velocity="30" />

</joint>

<link name="right_pinkie_finger_pip_2_link">
<visual>
<origin xyz="0.05049999999999996 -5.551115123125783e-17 0.0" rpy="-1.5707963267948966 -1.5707963267948966 0.0" />
<geometry>
<mesh filename="./lsa1.1_new//meshes/urdf/obj_combined_hulls/right_pinkie_finger_pip_2_link.obj" />
</geometry>
</visual>
<collision>
<origin xyz="0.05049999999999996 -5.551115123125783e-17 0.0" rpy="-1.5707963267948966 -1.5707963267948966 0.0" />
<geometry>
<mesh filename="./lsa1.1_new//meshes/urdf/obj_combined_hulls/right_pinkie_finger_pip_2_link.obj" />
</geometry>
</collision>
<inertial>
<origin xyz="-0.006998651016714586 -0.00017090217066062648 -4.597237124852314e-06" rpy="0 0 0" />
<mass value="0.008583915368359748" />
<inertia ixx="1.6902733152710736e-07" ixy="1.0810765846070588e-08" ixz="1.6979113593063312e-10" iyy="3.536501590407653e-07" iyz="-2.514557349728269e-11" izz="3.0354744604914976e-07" />
</inertial>
</link>

<joint name="right_pinkie_finger_pip_2" type="continuous">
<origin xyz="-0.007000000000000006 -2.7755575615628914e-17 0.0" rpy="-5.758578568950262e-26 2.105044001754451e-28 7.15662238388339e-15" />
<parent link="right_pinkie_finger_pip_link" />
<child link="right_pinkie_finger_pip_2_link" />
<axis xyz="2.123250450230173e-28 5.759273065210589e-26 1.0" />
<mimic joint="right_pinkie_finger_pip" multiplier="1.0" offset="0" />
<limit effort="30" velocity="30" />

</joint>

<link name="right_index_finger_pip_2_link">
<visual>
<origin xyz="0.050499999999999934 0.0 0.0" rpy="-1.5707963267948966 -1.5707963267948966 0.0" />
<geometry>
<mesh filename="./lsa1.1_new//meshes/urdf/obj_combined_hulls/right_index_finger_pip_2_link.obj" />
</geometry>
</visual>
<collision>
<origin xyz="0.050499999999999934 0.0 0.0" rpy="-1.5707963267948966 -1.5707963267948966 0.0" />
<geometry>
<mesh filename="./lsa1.1_new//meshes/urdf/obj_combined_hulls/right_index_finger_pip_2_link.obj" />
</geometry>
</collision>
<inertial>
<origin xyz="-0.006998651016720324 -0.00017090217064890675 -4.597237124654432e-06" rpy="0 0 0" />
<mass value="0.008583915368359746" />
<inertia ixx="1.6902733152684918e-07" ixy="1.0810765845639629e-08" ixz="1.6979113592997994e-10" iyy="3.5365015904116267e-07" iyz="-2.5145573516566598e-11" izz="3.0354744604927073e-07" />
</inertial>
</link>

<joint name="right_index_finger_pip_2" type="continuous">
<origin xyz="-0.007000000000000006 0.0 -3.469446951953614e-18" rpy="9.603429162981583e-15 1.5925979214644672e-14 1.208910172728418e-14" />
<parent link="right_index_finger_pip_link" />
<child link="right_index_finger_pip_2_link" />
<axis xyz="1.5925979214644653e-14 -9.603429162981397e-15 0.9999999999999911" />
<mimic joint="right_index_finger_pip" multiplier="1.0" offset="0" />
<limit effort="30" velocity="30" />

</joint>

<link name="right_ring_finger_pip_2_link">
<visual>
<origin xyz="0.05049999999999996 -2.7755575615628914e-17 0.0" rpy="-1.5707963267948966 -1.5707963267948966 0.0" />
<geometry>
<mesh filename="./lsa1.1_new//meshes/urdf/obj_combined_hulls/right_ring_finger_pip_2_link.obj" />
</geometry>
</visual>
<collision>
<origin xyz="0.05049999999999996 -2.7755575615628914e-17 0.0" rpy="-1.5707963267948966 -1.5707963267948966 0.0" />
<geometry>
<mesh filename="./lsa1.1_new//meshes/urdf/obj_combined_hulls/right_ring_finger_pip_2_link.obj" />
</geometry>
</collision>
<inertial>
<origin xyz="-0.006998651016719726 -0.00017090217064913345 -4.597237124486389e-06" rpy="0 0 0" />
<mass value="0.008583915368359746" />
<inertia ixx="1.6902733152684664e-07" ixy="1.0810765845625664e-08" ixz="1.6979113594287204e-10" iyy="3.536501590411366e-07" iyz="-2.5145573513369338e-11" izz="3.035474460492601e-07" />
</inertial>
</link>

<joint name="right_ring_finger_pip_2" type="continuous">
<origin xyz="-0.007000000000000006 0.0 -6.938893903907228e-18" rpy="-1.530517368343981e-26 -6.123233995715212e-17 1.1978079424886192e-14" />
<parent link="right_ring_finger_pip_link" />
<child link="right_ring_finger_pip_2_link" />
<axis xyz="-6.12323399571521e-17 1.530664028192541e-26 1.0" />
<mimic joint="right_ring_finger_pip" multiplier="1.0" offset="0" />
<limit effort="30" velocity="30" />

</joint>

<link name="right_thumb_mcp_flexion_2_link">
<visual>
<origin xyz="0.020000000000000073 -1.3877787807814457e-17 0.0" rpy="-1.5707963267948966 -1.5707963267948966 0.0" />
<geometry>
<mesh filename="./lsa1.1_new//meshes/urdf/obj_combined_hulls/right_thumb_mcp_flexion_2_link.obj" />
</geometry>
</visual>
<collision>
<origin xyz="0.020000000000000073 -1.3877787807814457e-17 0.0" rpy="-1.5707963267948966 -1.5707963267948966 0.0" />
<geometry>
<mesh filename="./lsa1.1_new//meshes/urdf/obj_combined_hulls/right_thumb_mcp_flexion_2_link.obj" />
</geometry>
</collision>
<inertial>
<origin xyz="-0.0140015395704227 -0.001083752575066778 0.0009893031479127317" rpy="0 0 0" />
<mass value="0.020219104467145074" />
<inertia ixx="5.3609630299966e-07" ixy="1.2571078108833194e-07" ixz="-4.8202677355822776e-08" iyy="1.8573644501004077e-06" iyz="-4.617846315001294e-09" izz="1.9503453341749937e-06" />
</inertial>
</link>

<joint name="right_thumb_mcp_flexion_2" type="continuous">
<origin xyz="-0.010000000000000148 5.551115123125783e-17 -1.3877787807814457e-16" rpy="6.522145755114473e-15 2.0395995436792588e-14 -1.1120013257697989e-14" />
<parent link="right_thumb_mcp_flexion_link" />
<child link="right_thumb_mcp_flexion_2_link" />
<axis xyz="2.039599543679279e-14 -6.5221457551130766e-15 1.0000000000000113" />
<mimic joint="right_thumb_mcp_flexion" multiplier="1.0" offset="0" />
<limit effort="30" velocity="30" />

</joint>

<link name="left_thumb_mcp_flexion_2_link">
<visual>
<origin xyz="0.020000000000000073 -1.3877787807814457e-17 0.0" rpy="-1.5707963267948966 -1.5707963267948966 0.0" />
<geometry>
<mesh filename="./lsa1.1_new//meshes/urdf/obj_combined_hulls/left_thumb_mcp_flexion_2_link.obj" />
</geometry>
</visual>
<collision>
<origin xyz="0.020000000000000073 -1.3877787807814457e-17 0.0" rpy="-1.5707963267948966 -1.5707963267948966 0.0" />
<geometry>
<mesh filename="./lsa1.1_new//meshes/urdf/obj_combined_hulls/left_thumb_mcp_flexion_2_link.obj" />
</geometry>
</collision>
<inertial>
<origin xyz="-0.014001546183678527 -0.0010837575737929702 -0.0007779312466643468" rpy="0 0 0" />
<mass value="0.02021907524408128" />
<inertia ixx="5.436486419520082e-07" ixy="1.2571052055044268e-07" ixz="2.7845956543120073e-08" iyy="1.8649129978238748e-06" iyz="-1.4917687152876038e-08" izz="1.9503411802931578e-06" />
</inertial>
</link>

<joint name="left_thumb_mcp_flexion_2" type="continuous">
<origin xyz="-0.009999999999999357 8.465450562766819e-16 -4.191091917959966e-15" rpy="-1.457097342871686e-15 1.2236020668789367e-15 -1.0580432349028161e-16" />
<parent link="left_thumb_mcp_flexion_link" />
<child link="left_thumb_mcp_flexion_2_link" />
<axis xyz="1.2236020668789645e-15 1.4570973428717123e-15 1.0000000000000313" />
<mimic joint="left_thumb_mcp_flexion" multiplier="1.0" offset="0" />
<limit effort="30" velocity="30" />

</joint>

<link name="left_middle_finger_pip_2_link">
<visual>
<origin xyz="0.05049999999999999 0.0 6.938893903907228e-18" rpy="-1.5707963267948966 -1.5707963267948966 0.0" />
<geometry>
<mesh filename="./lsa1.1_new//meshes/urdf/obj_combined_hulls/left_middle_finger_pip_2_link.obj" />
</geometry>
</visual>
<collision>
<origin xyz="0.05049999999999999 0.0 6.938893903907228e-18" rpy="-1.5707963267948966 -1.5707963267948966 0.0" />
<geometry>
<mesh filename="./lsa1.1_new//meshes/urdf/obj_combined_hulls/left_middle_finger_pip_2_link.obj" />
</geometry>
</collision>
<inertial>
<origin xyz="-0.006998651016722202 -0.00017090217065563482 -4.597237146989101e-06" rpy="0 0 0" />
<mass value="0.008583915368359748" />
<inertia ixx="1.6902733152698814e-07" ixy="1.0810765845891036e-08" ixz="1.6979113582058558e-10" iyy="3.536501590409895e-07" iyz="-2.514557343511955e-11" izz="3.0354744604925405e-07" />
</inertial>
</link>

<joint name="left_middle_finger_pip_2" type="continuous">
<origin xyz="-0.007000000000000006 0.0 0.0" rpy="2.8713674189745045e-24 -6.12323409651856e-17 -4.5116607789941424e-14" />
<parent link="left_middle_finger_pip_link" />
<child link="left_middle_finger_pip_2_link" />
<axis xyz="-6.12323409651856e-17 -2.8713700883063724e-24 1.0000000000000009" />
<mimic joint="left_middle_finger_pip" multiplier="1.0" offset="0" />
<limit effort="30" velocity="30" />

</joint>

<link name="left_pinkie_finger_pip_2_link">
<visual>
<origin xyz="0.05049999999999999 -2.7755575615628914e-17 0.0" rpy="-1.5707963267948966 -1.5707963267948966 0.0" />
<geometry>
<mesh filename="./lsa1.1_new//meshes/urdf/obj_combined_hulls/left_pinkie_finger_pip_2_link.obj" />
</geometry>
</visual>
<collision>
<origin xyz="0.05049999999999999 -2.7755575615628914e-17 0.0" rpy="-1.5707963267948966 -1.5707963267948966 0.0" />
<geometry>
<mesh filename="./lsa1.1_new//meshes/urdf/obj_combined_hulls/left_pinkie_finger_pip_2_link.obj" />
</geometry>
</collision>
<inertial>
<origin xyz="-0.006998651016722406 -0.00017090217065560625 -4.597237147022699e-06" rpy="0 0 0" />
<mass value="0.008583915368359746" />
<inertia ixx="1.6902733152698581e-07" ixy="1.0810765845890984e-08" ixz="1.6979113581946026e-10" iyy="3.536501590409906e-07" iyz="-2.514557343605292e-11" izz="3.0354744604925675e-07" />
</inertial>
</link>

<joint name="left_pinkie_finger_pip_2" type="continuous">
<origin xyz="-0.0069999999999999785 0.0 0.0" rpy="1.6800476021322353e-24 -6.123234261954671e-17 -4.207881063275866e-14" />
<parent link="left_pinkie_finger_pip_link" />
<child link="left_pinkie_finger_pip_2_link" />
<axis xyz="-6.12323426195467e-17 -1.680052192426099e-24 1.0000000000000007" />
<mimic joint="left_pinkie_finger_pip" multiplier="1.0" offset="0" />
<limit effort="30" velocity="30" />

</joint>

<link name="left_index_finger_pip_2_link">
<visual>
<origin xyz="0.05049999999999999 0.0 0.0" rpy="-1.5707963267948966 -1.5707963267948966 0.0" />
<geometry>
<mesh filename="./lsa1.1_new//meshes/urdf/obj_combined_hulls/left_index_finger_pip_2_link.obj" />
</geometry>
</visual>
<collision>
<origin xyz="0.05049999999999999 0.0 0.0" rpy="-1.5707963267948966 -1.5707963267948966 0.0" />
<geometry>
<mesh filename="./lsa1.1_new//meshes/urdf/obj_combined_hulls/left_index_finger_pip_2_link.obj" />
</geometry>
</collision>
<inertial>
<origin xyz="-0.006998651016718398 -0.00017090217065493946 -4.597237146911776e-06" rpy="0 0 0" />
<mass value="0.008583915368359748" />
<inertia ixx="1.6902733152699476e-07" ixy="1.081076584587938e-08" ixz="1.697911358168629e-10" iyy="3.536501590409595e-07" iyz="-2.51455734549951e-11" izz="3.035474460492195e-07" />
</inertial>
</link>

<joint name="left_index_finger_pip_2" type="continuous">
<origin xyz="-0.006999999999999951 -2.7755575615628914e-17 0.0" rpy="5.105167530527408e-16 -1.1389112050126868e-15 -4.367722303493347e-14" />
<parent link="left_index_finger_pip_link" />
<child link="left_index_finger_pip_2_link" />
<axis xyz="-1.1389112054108758e-15 -5.105167530527205e-16 1.0000000000000355" />
<mimic joint="left_index_finger_pip" multiplier="1.0" offset="0" />
<limit effort="30" velocity="30" />

</joint>

<link name="left_ring_finger_pip_2_link">
<visual>
<origin xyz="0.05049999999999999 0.0 0.0" rpy="-1.5707963267948966 -1.5707963267948966 0.0" />
<geometry>
<mesh filename="./lsa1.1_new//meshes/urdf/obj_combined_hulls/left_ring_finger_pip_2_link.obj" />
</geometry>
</visual>
<collision>
<origin xyz="0.05049999999999999 0.0 0.0" rpy="-1.5707963267948966 -1.5707963267948966 0.0" />
<geometry>
<mesh filename="./lsa1.1_new//meshes/urdf/obj_combined_hulls/left_ring_finger_pip_2_link.obj" />
</geometry>
</collision>
<inertial>
<origin xyz="-0.006998651016722346 -0.0001709021706541728 -4.597237146977622e-06" rpy="0 0 0" />
<mass value="0.008583915368359748" />
<inertia ixx="1.6902733152699256e-07" ixy="1.0810765845874773e-08" ixz="1.6979113582832164e-10" iyy="3.5365015904098717e-07" iyz="-2.514557347984257e-11" izz="3.035474460492558e-07" />
</inertial>
</link>

<joint name="left_ring_finger_pip_2" type="continuous">
<origin xyz="-0.006999999999999923 2.7755575615628914e-17 0.0" rpy="-1.0554286607085916e-25 -1.8369701796160783e-16 -4.367722303493524e-14" />
<parent link="left_ring_finger_pip_link" />
<child link="left_ring_finger_pip_2_link" />
<axis xyz="-1.836970179713195e-16 1.0555310594520812e-25 0.9999999999999997" />
<mimic joint="left_ring_finger_pip" multiplier="1.0" offset="0" />
<limit effort="30" velocity="30" />

</joint>

<link name="right_middle_finger_dip_link">
<visual>
<origin xyz="0.0655 0.0 0.0" rpy="-1.5707963267948966 -1.5707963267948966 0.0" />
<geometry>
<mesh filename="./lsa1.1_new//meshes/urdf/obj_combined_hulls/right_middle_finger_dip_link.obj" />
</geometry>
</visual>
<collision>
<origin xyz="0.0655 0.0 0.0" rpy="-1.5707963267948966 -1.5707963267948966 0.0" />
<geometry>
<mesh filename="./lsa1.1_new//meshes/urdf/obj_combined_hulls/right_middle_finger_dip_link.obj" />
</geometry>
</collision>
<inertial>
<origin xyz="-0.002021651763259658 0.00028003225702250863 -4.773922732104691e-06" rpy="0 0 0" />
<mass value="0.0009634174877579615" />
<inertia ixx="4.414391066839755e-09" ixy="-9.230109813476016e-10" ixz="-2.199237518566974e-12" iyy="9.447112023641094e-09" iyz="-1.286533690563166e-12" izz="6.936467962084979e-09" />
</inertial>
</link>

<joint name="right_middle_finger_dip" type="continuous">
<origin xyz="-0.015000000000000041 -2.7755575615628914e-17 -6.938893903907228e-18" rpy="9.769962616719913e-15 -6.123233995746799e-17 -6.331460571747394e-30" />
<parent link="right_middle_finger_pip_2_link" />
<child link="right_middle_finger_dip_link" />
<axis xyz="-6.123233995746757e-17 -9.769962616719993e-15 0.9999999999999913" />
<mimic joint="right_middle_finger_pip" multiplier="0.7727272727272727" offset="0" />
<limit effort="30" velocity="30" />

</joint>

<link name="right_pinkie_finger_dip_link">
<visual>
<origin xyz="0.06550000000000006 -2.7755575615628914e-17 1.3877787807814457e-17" rpy="-1.5707963267948966 -1.5707963267948966 0.0" />
<geometry>
<mesh filename="./lsa1.1_new//meshes/urdf/obj_combined_hulls/right_pinkie_finger_dip_link.obj" />
</geometry>
</visual>
<collision>
<origin xyz="0.06550000000000006 -2.7755575615628914e-17 1.3877787807814457e-17" rpy="-1.5707963267948966 -1.5707963267948966 0.0" />
<geometry>
<mesh filename="./lsa1.1_new//meshes/urdf/obj_combined_hulls/right_pinkie_finger_dip_link.obj" />
</geometry>
</collision>
<inertial>
<origin xyz="-0.0020216517632595946 0.000280032257022477 -4.773922732088907e-06" rpy="0 0 0" />
<mass value="0.0009634174877579615" />
<inertia ixx="4.4143910668399725e-09" ixy="-9.230109813476211e-10" ixz="-2.1992375186062174e-12" iyy="9.447112023641007e-09" iyz="-1.2865336905413903e-12" izz="6.936467962084939e-09" />
</inertial>
</link>

<joint name="right_pinkie_finger_dip" type="continuous">
<origin xyz="-0.015000000000000069 -5.551115123125783e-17 0.0" rpy="5.771412421759759e-26 -6.123233995733062e-17 6.980435495936982e-27" />
<parent link="right_pinkie_finger_pip_2_link" />
<child link="right_pinkie_finger_dip_link" />
<axis xyz="-6.123233995732881e-17 -5.770172532962143e-26 1.0" />
<mimic joint="right_pinkie_finger_pip" multiplier="0.7727272727272727" offset="0" />
<limit effort="30" velocity="30" />

</joint>

<link name="right_index_finger_dip_link">
<visual>
<origin xyz="0.06550000000000006 0.0 -3.469446951953614e-18" rpy="-1.5707963267948966 -1.5707963267948966 0.0" />
<geometry>
<mesh filename="./lsa1.1_new//meshes/urdf/obj_combined_hulls/right_index_finger_dip_link.obj" />
</geometry>
</visual>
<collision>
<origin xyz="0.06550000000000006 0.0 -3.469446951953614e-18" rpy="-1.5707963267948966 -1.5707963267948966 0.0" />
<geometry>
<mesh filename="./lsa1.1_new//meshes/urdf/obj_combined_hulls/right_index_finger_dip_link.obj" />
</geometry>
</collision>
<inertial>
<origin xyz="-0.0020216517632596024 0.0002800322570225086 -4.773922732108646e-06" rpy="0 0 0" />
<mass value="0.0009634174877579615" />
<inertia ixx="4.414391066839753e-09" ixy="-9.23010981347601e-10" ixz="-2.199237518567885e-12" iyy="9.44711202364109e-09" iyz="-1.2865336905628126e-12" izz="6.936467962084979e-09" />
</inertial>
</link>

<joint name="right_index_finger_dip" type="continuous">
<origin xyz="-0.015000000000000152 0.0 6.938893903907228e-18" rpy="-9.603429162981742e-15 -1.6516340188144223e-14 2.5243548967073633e-29" />
<parent link="right_index_finger_pip_2_link" />
<child link="right_index_finger_dip_link" />
<axis xyz="-1.651634018814437e-14 9.603429162981744e-15 1.0000000000000089" />
<mimic joint="right_index_finger_pip" multiplier="0.7727272727272727" offset="0" />
<limit effort="30" velocity="30" />

</joint>

<link name="right_ring_finger_dip_link">
<visual>
<origin xyz="0.06550000000000003 0.0 0.0" rpy="-1.5707963267948966 -1.5707963267948966 0.0" />
<geometry>
<mesh filename="./lsa1.1_new//meshes/urdf/obj_combined_hulls/right_ring_finger_dip_link.obj" />
</geometry>
</visual>
<collision>
<origin xyz="0.06550000000000003 0.0 0.0" rpy="-1.5707963267948966 -1.5707963267948966 0.0" />
<geometry>
<mesh filename="./lsa1.1_new//meshes/urdf/obj_combined_hulls/right_ring_finger_dip_link.obj" />
</geometry>
</collision>
<inertial>
<origin xyz="-0.002021651763259638 0.0002800322570225086 -4.773922732104647e-06" rpy="0 0 0" />
<mass value="0.0009634174877579615" />
<inertia ixx="4.4143910668395365e-09" ixy="-9.230109813475915e-10" ixz="-2.1992375185304322e-12" iyy="9.447112023641137e-09" iyz="-1.2865336905833713e-12" izz="6.936467962084985e-09" />
</inertial>
</link>

<joint name="right_ring_finger_dip" type="continuous">
<origin xyz="-0.015000000000000097 -2.7755575615628914e-17 0.0" rpy="9.492406860546969e-15 -6.12323399572665e-17 -5.143047488740217e-30" />
<parent link="right_ring_finger_pip_2_link" />
<child link="right_ring_finger_dip_link" />
<axis xyz="-6.123233995726749e-17 -9.492406860547042e-15 0.9999999999999911" />
<mimic joint="right_ring_finger_pip" multiplier="0.7727272727272727" offset="0" />
<limit effort="30" velocity="30" />

</joint>

<link name="right_thumb_dip_link">
<visual>
<origin xyz="0.04808854433117703 1.3877787807814457e-17 0.0" rpy="-1.5707963267948966 -1.5707963267948966 0.0" />
<geometry>
<mesh filename="./lsa1.1_new//meshes/urdf/obj_combined_hulls/right_thumb_dip_link.obj" />
</geometry>
</visual>
<collision>
<origin xyz="0.04808854433117703 1.3877787807814457e-17 0.0" rpy="-1.5707963267948966 -1.5707963267948966 0.0" />
<geometry>
<mesh filename="./lsa1.1_new//meshes/urdf/obj_combined_hulls/right_thumb_dip_link.obj" />
</geometry>
</collision>
<inertial>
<origin xyz="-0.0029634443099262565 0.0013916529212620117 -5.9929333125712115e-06" rpy="0 0 0" />
<mass value="0.0027238010005492023" />
<inertia ixx="2.174842462772807e-08" ixy="1.9296433345440833e-09" ixz="4.190312584288959e-11" iyy="3.303405207007644e-08" iyz="-3.834380579451865e-11" izz="4.1391392884038595e-08" />
</inertial>
</link>

<joint name="right_thumb_dip" type="revolute">
<origin xyz="-0.028088544331176954 -2.7755575615628914e-17 5.717648576819556e-14" rpy="-6.9817158537839245e-15 -1.8622697724577205e-14 3.33146031195445e-15" />
<parent link="right_thumb_mcp_flexion_2_link" />
<child link="right_thumb_dip_link" />
<axis xyz="-1.8622697724577442e-14 6.981715853785225e-15 1.0000000000000149" />
<limit effort="30" velocity="30" lower="0" upper="0.7853981633974483" />

</joint>

<link name="left_thumb_dip_link">
<visual>
<origin xyz="0.048088544331176986 2.7755575615628914e-17 0.0" rpy="-1.5707963267948966 -1.5707963267948966 0.0" />
<geometry>
<mesh filename="./lsa1.1_new//meshes/urdf/obj_combined_hulls/left_thumb_dip_link.obj" />
</geometry>
</visual>
<collision>
<origin xyz="0.048088544331176986 2.7755575615628914e-17 0.0" rpy="-1.5707963267948966 -1.5707963267948966 0.0" />
<geometry>
<mesh filename="./lsa1.1_new//meshes/urdf/obj_combined_hulls/left_thumb_dip_link.obj" />
</geometry>
</collision>
<inertial>
<origin xyz="-0.002963444309926285 0.001391652849145585 5.992933312595507e-06" rpy="0 0 0" />
<mass value="0.0027238010005492023" />
<inertia ixx="2.1748423703876306e-08" ixy="1.9296442212228618e-09" ixz="-4.190312584298141e-11" iyy="3.303405207007674e-08" iyz="3.833356848915667e-11" izz="4.1391391960186986e-08" />
</inertial>
</link>

<joint name="left_thumb_dip" type="revolute">
<origin xyz="-0.02808854433116932 6.827871601444713e-15 6.342149028171207e-14" rpy="5.425604762308508e-17 1.0979237696911871e-16 1.699711882676685e-15" />
<parent link="left_thumb_mcp_flexion_2_link" />
<child link="left_thumb_dip_link" />
<axis xyz="1.0979237696913305e-16 -5.425604762307121e-17 1.0" />
<limit effort="30" velocity="30" lower="0" upper="0.7853981633974483" />

</joint>

<link name="left_middle_finger_dip_link">
<visual>
<origin xyz="0.06549999999999997 0.0 -6.938893903907228e-18" rpy="-1.5707963267948966 -1.5707963267948966 0.0" />
<geometry>
<mesh filename="./lsa1.1_new//meshes/urdf/obj_combined_hulls/left_middle_finger_dip_link.obj" />
</geometry>
</visual>
<collision>
<origin xyz="0.06549999999999997 0.0 -6.938893903907228e-18" rpy="-1.5707963267948966 -1.5707963267948966 0.0" />
<geometry>
<mesh filename="./lsa1.1_new//meshes/urdf/obj_combined_hulls/left_middle_finger_dip_link.obj" />
</geometry>
</collision>
<inertial>
<origin xyz="-0.0020216517632596857 0.0002800322570225008 -4.7739227321097755e-06" rpy="0 0 0" />
<mass value="0.0009634174877579615" />
<inertia ixx="4.414391066839808e-09" ixy="-9.230109813476194e-10" ixz="-2.1992375185656427e-12" iyy="9.447112023641189e-09" iyz="-1.2865336905623732e-12" izz="6.9364679620849494e-09" />
</inertial>
</link>

<joint name="left_middle_finger_dip" type="continuous">
<origin xyz="-0.015000000000000041 0.0 0.0" rpy="-1.684741136233002e-24 -6.123233932053594e-17 0.0" />
<parent link="left_middle_finger_pip_2_link" />
<child link="left_middle_finger_dip_link" />
<axis xyz="-6.12323393302475e-17 1.6847309716105744e-24 0.9999999999999997" />
<mimic joint="left_middle_finger_pip" multiplier="0.7727272727272727" offset="0" />
<limit effort="30" velocity="30" />

</joint>

<link name="left_pinkie_finger_dip_link">
<visual>
<origin xyz="0.06550000000000009 0.0 0.0" rpy="-1.5707963267948966 -1.5707963267948966 0.0" />
<geometry>
<mesh filename="./lsa1.1_new//meshes/urdf/obj_combined_hulls/left_pinkie_finger_dip_link.obj" />
</geometry>
</visual>
<collision>
<origin xyz="0.06550000000000009 0.0 0.0" rpy="-1.5707963267948966 -1.5707963267948966 0.0" />
<geometry>
<mesh filename="./lsa1.1_new//meshes/urdf/obj_combined_hulls/left_pinkie_finger_dip_link.obj" />
</geometry>
</collision>
<inertial>
<origin xyz="-0.0020216517632595725 0.00028003225702250467 -4.773922732104828e-06" rpy="0 0 0" />
<mass value="0.0009634174877579615" />
<inertia ixx="4.414391066839831e-09" ixy="-9.23010981347608e-10" ixz="-2.1992375185667656e-12" iyy="9.44711202364131e-09" iyz="-1.2865336905632072e-12" izz="6.9364679620849966e-09" />
</inertial>
</link>

<joint name="left_pinkie_finger_dip" type="continuous">
<origin xyz="-0.015000000000000041 -2.7755575615628914e-17 0.0" rpy="-1.406210185215964e-27 9.711686698029658e-27 2.5964396935292e-30" />
<parent link="left_pinkie_finger_pip_2_link" />
<child link="left_pinkie_finger_dip_link" />
<axis xyz="-9.711686698029657e-27 1.3958240222690845e-27 1.0" />
<mimic joint="left_pinkie_finger_pip" multiplier="0.7727272727272727" offset="0" />
<limit effort="30" velocity="30" />

</joint>

<link name="left_index_finger_dip_link">
<visual>
<origin xyz="0.06550000000000006 -2.7755575615628914e-17 -3.469446951953614e-18" rpy="-1.5707963267948966 -1.5707963267948966 0.0" />
<geometry>
<mesh filename="./lsa1.1_new//meshes/urdf/obj_combined_hulls/left_index_finger_dip_link.obj" />
</geometry>
</visual>
<collision>
<origin xyz="0.06550000000000006 -2.7755575615628914e-17 -3.469446951953614e-18" rpy="-1.5707963267948966 -1.5707963267948966 0.0" />
<geometry>
<mesh filename="./lsa1.1_new//meshes/urdf/obj_combined_hulls/left_index_finger_dip_link.obj" />
</geometry>
</collision>
<inertial>
<origin xyz="-0.0020216517632596098 0.000280032257022477 -4.773922732107615e-06" rpy="0 0 0" />
<mass value="0.0009634174877579615" />
<inertia ixx="4.414391066839678e-09" ixy="-9.230109813476771e-10" ixz="-2.1992375185648664e-12" iyy="9.447112023640979e-09" iyz="-1.2865336905682577e-12" izz="6.936467962085024e-09" />
</inertial>
</link>

<joint name="left_index_finger_dip" type="continuous">
<origin xyz="-0.015000000000000069 0.0 0.0" rpy="2.6034025699978705e-15 -4.2719428485332237e-16 1.1941335560600071e-29" />
<parent link="left_index_finger_pip_2_link" />
<child link="left_index_finger_dip_link" />
<axis xyz="-4.27194284076395e-16 -2.603402569997765e-15 0.9999999999999875" />
<mimic joint="left_index_finger_pip" multiplier="0.7727272727272727" offset="0" />
<limit effort="30" velocity="30" />

</joint>

<link name="left_ring_finger_dip_link">
<visual>
<origin xyz="0.06550000000000006 0.0 6.938893903907228e-18" rpy="-1.5707963267948966 -1.5707963267948966 0.0" />
<geometry>
<mesh filename="./lsa1.1_new//meshes/urdf/obj_combined_hulls/left_ring_finger_dip_link.obj" />
</geometry>
</visual>
<collision>
<origin xyz="0.06550000000000006 0.0 6.938893903907228e-18" rpy="-1.5707963267948966 -1.5707963267948966 0.0" />
<geometry>
<mesh filename="./lsa1.1_new//meshes/urdf/obj_combined_hulls/left_ring_finger_dip_link.obj" />
</geometry>
</collision>
<inertial>
<origin xyz="-0.0020216517632596024 0.0002800322570225086 -4.773922732097749e-06" rpy="0 0 0" />
<mass value="0.0009634174877579615" />
<inertia ixx="4.414391066839753e-09" ixy="-9.23010981347619e-10" ixz="-2.1992375185664877e-12" iyy="9.44711202364109e-09" iyz="-1.2865336905626807e-12" izz="6.936467962084979e-09" />
</inertial>
</link>

<joint name="left_ring_finger_dip" type="continuous">
<origin xyz="-0.015000000000000069 0.0 -1.3877787807814457e-17" rpy="-4.4835318395069555e-26 -1.2246467864107189e-16 0.0" />
<parent link="left_ring_finger_pip_2_link" />
<child link="left_ring_finger_dip_link" />
<axis xyz="-1.2246467864107189e-16 4.483856974909647e-26 1.0" />
<mimic joint="left_ring_finger_pip" multiplier="0.7727272727272727" offset="0" />
<limit effort="30" velocity="30" />

</joint>

<link name="right_middle_finger_dip_2_link">
<visual>
<origin xyz="0.07050000000000009 0.0 0.0" rpy="-1.5707963267948966 -1.5707963267948966 0.0" />
<geometry>
<mesh filename="./lsa1.1_new//meshes/urdf/obj_combined_hulls/right_middle_finger_dip_2_link.obj" />
</geometry>
</visual>
<collision>
<origin xyz="0.07050000000000009 0.0 0.0" rpy="-1.5707963267948966 -1.5707963267948966 0.0" />
<geometry>
<mesh filename="./lsa1.1_new//meshes/urdf/obj_combined_hulls/right_middle_finger_dip_2_link.obj" />
</geometry>
</collision>
<inertial>
<origin xyz="-0.006998629676404749 -2.149600260239774e-05 2.8862154116492625e-05" rpy="0 0 0" />
<mass value="0.005736094286194946" />
<inertia ixx="1.3944457847193885e-07" ixy="8.01184788535915e-09" ixz="2.0426282897105698e-10" iyy="2.429446874342036e-07" iyz="-9.319543682708947e-11" izz="1.79367878032205e-07" />
</inertial>
</link>

<joint name="right_middle_finger_dip_2" type="continuous">
<origin xyz="-0.00500000000000006 2.7755575615628914e-17 0.0" rpy="-5.551115126444608e-17 5.551115123046815e-17 6.884520453176422e-30" />
<parent link="right_middle_finger_dip_link" />
<child link="right_middle_finger_dip_2_link" />
<axis xyz="5.551115123046799e-17 5.551115126445574e-17 1.0" />
<mimic joint="right_middle_finger_dip" multiplier="1.0" offset="0" />
<limit effort="30" velocity="30" />

</joint>

<link name="right_middle_finger_tracker_link" />

<joint name="right_middle_finger_tracker" type="fixed">
<origin xyz="-0.015749999999999195 0.0011925164027886224 1.623000709810453e-14" rpy="1.5707963267949028 1.110223024626699e-15 -3.1415926535897833" />
<parent link="right_middle_finger_dip_2_link" />
<child link="right_middle_finger_tracker_link" />
</joint>

<link name="right_pinkie_finger_dip_2_link">
<visual>
<origin xyz="0.07050000000000003 -2.7755575615628914e-17 0.0" rpy="-1.5707963267948966 -1.5707963267948966 0.0" />
<geometry>
<mesh filename="./lsa1.1_new//meshes/urdf/obj_combined_hulls/right_pinkie_finger_dip_2_link.obj" />
</geometry>
</visual>
<collision>
<origin xyz="0.07050000000000003 -2.7755575615628914e-17 0.0" rpy="-1.5707963267948966 -1.5707963267948966 0.0" />
<geometry>
<mesh filename="./lsa1.1_new//meshes/urdf/obj_combined_hulls/right_pinkie_finger_dip_2_link.obj" />
</geometry>
</collision>
<inertial>
<origin xyz="-0.00699862967640467 -2.149600260301248e-05 2.8862154116205226e-05" rpy="0 0 0" />
<mass value="0.005736094286194946" />
<inertia ixx="1.3944457847193943e-07" ixy="8.0118478853596e-09" ixz="2.0426282896926853e-10" iyy="2.42944687434198e-07" iyz="-9.319543682568256e-11" izz="1.7936787803220004e-07" />
</inertial>
</link>

<joint name="right_pinkie_finger_dip_2" type="continuous">
<origin xyz="-0.004999999999999893 -2.7755575615628914e-17 1.3877787807814457e-17" rpy="-5.77269688785885e-26 -8.96726113051673e-31 -7.004490631821117e-27" />
<parent link="right_pinkie_finger_dip_link" />
<child link="right_pinkie_finger_dip_2_link" />
<axis xyz="8.96726113051673e-31 5.773702409679772e-26 1.0" />
<mimic joint="right_pinkie_finger_dip" multiplier="1.0" offset="0" />
<limit effort="30" velocity="30" />

</joint>

<link name="right_pinkie_finger_tracker_link" />

<joint name="right_pinkie_finger_tracker" type="fixed">
<origin xyz="-0.015749999999999514 0.0011925164027670355 8.636184132061725e-15" rpy="1.5707963267948994 3.019387618668942e-16 -3.1415926535897887" />
<parent link="right_pinkie_finger_dip_2_link" />
<child link="right_pinkie_finger_tracker_link" />
</joint>

<link name="right_index_finger_dip_2_link">
<visual>
<origin xyz="0.07050000000000003 -2.7755575615628914e-17 -3.469446951953614e-18" rpy="-1.5707963267948966 -1.5707963267948966 0.0" />
<geometry>
<mesh filename="./lsa1.1_new//meshes/urdf/obj_combined_hulls/right_index_finger_dip_2_link.obj" />
</geometry>
</visual>
<collision>
<origin xyz="0.07050000000000003 -2.7755575615628914e-17 -3.469446951953614e-18" rpy="-1.5707963267948966 -1.5707963267948966 0.0" />
<geometry>
<mesh filename="./lsa1.1_new//meshes/urdf/obj_combined_hulls/right_index_finger_dip_2_link.obj" />
</geometry>
</collision>
<inertial>
<origin xyz="-0.006998629676404726 -2.1496002603038023e-05 2.8862154116251617e-05" rpy="0 0 0" />
<mass value="0.005736094286194947" />
<inertia ixx="1.394445784719413e-07" ixy="8.011847885359759e-09" ixz="2.0426282896979583e-10" iyy="2.4294468743419993e-07" iyz="-9.319543682497752e-11" izz="1.7936787803219967e-07" />
</inertial>
</link>

<joint name="right_index_finger_dip_2" type="continuous">
<origin xyz="-0.004999999999999949 2.7755575615628914e-17 -6.938893903907228e-18" rpy="-1.4764317014550414e-26 -2.376207666221599e-30 1.2027567942068819e-29" />
<parent link="right_index_finger_dip_link" />
<child link="right_index_finger_dip_2_link" />
<axis xyz="-3.1554436208840472e-30 1.4771801533813676e-26 1.0" />
<mimic joint="right_index_finger_dip" multiplier="1.0" offset="0" />
<limit effort="30" velocity="30" />

</joint>

<link name="right_index_finger_tracker_link" />

<joint name="right_index_finger_tracker" type="fixed">
<origin xyz="-0.015749999999999792 0.001192516402767687 8.79819070450841e-15" rpy="1.5707963267948997 -5.321979818863501e-16 3.141592653589784" />
<parent link="right_index_finger_dip_2_link" />
<child link="right_index_finger_tracker_link" />
</joint>

<link name="right_ring_finger_dip_2_link">
<visual>
<origin xyz="0.07050000000000006 -2.7755575615628914e-17 0.0" rpy="-1.5707963267948966 -1.5707963267948966 0.0" />
<geometry>
<mesh filename="./lsa1.1_new//meshes/urdf/obj_combined_hulls/right_ring_finger_dip_2_link.obj" />
</geometry>
</visual>
<collision>
<origin xyz="0.07050000000000006 -2.7755575615628914e-17 0.0" rpy="-1.5707963267948966 -1.5707963267948966 0.0" />
<geometry>
<mesh filename="./lsa1.1_new//meshes/urdf/obj_combined_hulls/right_ring_finger_dip_2_link.obj" />
</geometry>
</collision>
<inertial>
<origin xyz="-0.006998629676404468 -2.1496002603539944e-05 2.886215411645001e-05" rpy="0 0 0" />
<mass value="0.005736094286194946" />
<inertia ixx="1.3944457847193925e-07" ixy="8.011847885363838e-09" ixz="2.0426282896587893e-10" iyy="2.4294468743420136e-07" iyz="-9.319543680352884e-11" izz="1.79367878032201e-07" />
</inertial>
</link>

<joint name="right_ring_finger_dip_2" type="continuous">
<origin xyz="-0.0050000000000000044 2.7755575615628914e-17 0.0" rpy="-9.492406860552695e-15 -1.656613015065536e-14 -1.202756794206974e-29" />
<parent link="right_ring_finger_dip_link" />
<child link="right_ring_finger_dip_2_link" />
<axis xyz="-1.656613015065551e-14 9.492406860552707e-15 1.0000000000000089" />
<mimic joint="right_ring_finger_dip" multiplier="1.0" offset="0" />
<limit effort="30" velocity="30" />

</joint>

<link name="right_ring_finger_tracker_link" />

<joint name="right_ring_finger_tracker" type="fixed">
<origin xyz="-0.015749999999999098 0.0011925164027893852 1.6760499234782822e-14" rpy="1.5707963267948992 3.2040828946153195e-16 -3.141592653589788" />
<parent link="right_ring_finger_dip_2_link" />
<child link="right_ring_finger_tracker_link" />
</joint>

<link name="right_thumb_dip_2_link">
<visual>
<origin xyz="0.05608854433117699 -2.7755575615628914e-17 -2.7755575615628914e-17" rpy="-1.5707963267948968 -1.5707963267948966 0.0" />
<geometry>
<mesh filename="./lsa1.1_new//meshes/urdf/obj_combined_hulls/right_thumb_dip_2_link.obj" />
</geometry>
</visual>
<collision>
<origin xyz="0.05608854433117699 -2.7755575615628914e-17 -2.7755575615628914e-17" rpy="-1.5707963267948968 -1.5707963267948966 0.0" />
<geometry>
<mesh filename="./lsa1.1_new//meshes/urdf/obj_combined_hulls/right_thumb_dip_2_link.obj" />
</geometry>
</collision>
<inertial>
<origin xyz="-0.006872504825820687 0.0010424459892332946 0.0008622868722163027" rpy="0 0 0" />
<mass value="0.010698059398006428" />
<inertia ixx="2.603243187835652e-07" ixy="2.3143501022511388e-08" ixz="-1.2568739622615048e-08" iyy="4.413907145761324e-07" iyz="-3.0311811512693147e-09" izz="4.1902594453781596e-07" />
</inertial>
</link>

<joint name="right_thumb_dip_2" type="continuous">
<origin xyz="-0.007999999999999924 4.163336342344337e-17 2.7755575615628914e-17" rpy="7.123370024798734e-15 1.8132568235681083e-14 -3.307460981530759e-15" />
<parent link="right_thumb_dip_link" />
<child link="right_thumb_dip_2_link" />
<axis xyz="1.8132568235680787e-14 -7.123370024797468e-15 0.9999999999999851" />
<mimic joint="right_thumb_dip" multiplier="1.0" offset="0" />
<limit effort="30" velocity="30" />

</joint>

<link name="right_thumb_tracker_link" />

<joint name="right_thumb_tracker" type="fixed">
<origin xyz="-0.016199999999962786 0.002251713602631571 0.00016278731337560963" rpy="-3.141592653589774 1.4520251919855436e-14 3.1415926535897887" />
<parent link="right_thumb_dip_2_link" />
<child link="right_thumb_tracker_link" />
</joint>

<link name="left_thumb_dip_2_link">
<visual>
<origin xyz="0.05608854433117698 -1.3877787807814457e-17 -2.7755575615628914e-17" rpy="-1.5707963267948966 -1.5707963267948966 0.0" />
<geometry>
<mesh filename="./lsa1.1_new//meshes/urdf/obj_combined_hulls/left_thumb_dip_2_link.obj" />
</geometry>
</visual>
<collision>
<origin xyz="0.05608854433117698 -1.3877787807814457e-17 -2.7755575615628914e-17" rpy="-1.5707963267948966 -1.5707963267948966 0.0" />
<geometry>
<mesh filename="./lsa1.1_new//meshes/urdf/obj_combined_hulls/left_thumb_dip_2_link.obj" />
</geometry>
</collision>
<inertial>
<origin xyz="-0.006872503714559624 0.0010424429278638792 -0.0008631096378677558" rpy="0 0 0" />
<mass value="0.010698061622632803" />
<inertia ixx="2.603090665755908e-07" ixy="2.314344679957409e-08" ixz="1.2584958074853828e-08" iyy="4.4137565066271386e-07" iyz="3.0113442443291493e-09" izz="4.1902597074168725e-07" />
</inertial>
</link>

<joint name="left_thumb_dip_2" type="continuous">
<origin xyz="-0.00799999999999998 5.551115123125783e-17 8.326672684688674e-17" rpy="6.921263205508811e-17 -2.899766599755909e-16 -1.6610201180379216e-15" />
<parent link="left_thumb_dip_link" />
<child link="left_thumb_dip_2_link" />
<axis xyz="-2.899766599755815e-16 -6.921263205508229e-17 1.0" />
<mimic joint="left_thumb_dip" multiplier="1.0" offset="0" />
<limit effort="30" velocity="30" />

</joint>

<link name="left_thumb_tracker_link" />

<joint name="left_thumb_tracker" type="fixed">
<origin xyz="-0.016200000000144696 0.0022517136026238313 -0.0001627873138541483" rpy="1.9317880628477762e-14 1.3816555467856628e-14 3.1415926535897882" />
<parent link="left_thumb_dip_2_link" />
<child link="left_thumb_tracker_link" />
</joint>

<link name="left_middle_finger_dip_2_link">
<visual>
<origin xyz="0.07050000000000003 0.0 0.0" rpy="-1.5707963267948966 -1.5707963267948966 0.0" />
<geometry>
<mesh filename="./lsa1.1_new//meshes/urdf/obj_combined_hulls/left_middle_finger_dip_2_link.obj" />
</geometry>
</visual>
<collision>
<origin xyz="0.07050000000000003 0.0 0.0" rpy="-1.5707963267948966 -1.5707963267948966 0.0" />
<geometry>
<mesh filename="./lsa1.1_new//meshes/urdf/obj_combined_hulls/left_middle_finger_dip_2_link.obj" />
</geometry>
</collision>
<inertial>
<origin xyz="-0.00699862967640482 -2.1496002602477626e-05 2.8862154115840548e-05" rpy="0 0 0" />
<mass value="0.005736094286194947" />
<inertia ixx="1.394445784719402e-07" ixy="8.0118478853594e-09" ixz="2.042628289693355e-10" iyy="2.4294468743419315e-07" iyz="-9.319543682493928e-11" izz="1.793678780322002e-07" />
</inertial>
</link>

<joint name="left_middle_finger_dip_2" type="continuous">
<origin xyz="-0.0050000000000000044 0.0 0.0" rpy="-2.681375073955149e-16 6.123233882524567e-17 5.181253153811283e-30" />
<parent link="left_middle_finger_dip_link" />
<child link="left_middle_finger_dip_2_link" />
<axis xyz="6.123233932053594e-17 2.6813750739548264e-16 0.9999999999999806" />
<mimic joint="left_middle_finger_dip" multiplier="1.0" offset="0" />
<limit effort="30" velocity="30" />

</joint>

<link name="left_middle_finger_tracker_link" />

<joint name="left_middle_finger_tracker" type="fixed">
<origin xyz="-0.015750000000004316 0.001192516402784849 -5.286102355251794e-15" rpy="1.570796326794903 1.332267630055189e-15 -3.141592653589781" />
<parent link="left_middle_finger_dip_2_link" />
<child link="left_middle_finger_tracker_link" />
</joint>

<link name="left_pinkie_finger_dip_2_link">
<visual>
<origin xyz="0.07050000000000012 0.0 0.0" rpy="-1.5707963267948966 -1.5707963267948966 0.0" />
<geometry>
<mesh filename="./lsa1.1_new//meshes/urdf/obj_combined_hulls/left_pinkie_finger_dip_2_link.obj" />
</geometry>
</visual>
<collision>
<origin xyz="0.07050000000000012 0.0 0.0" rpy="-1.5707963267948966 -1.5707963267948966 0.0" />
<geometry>
<mesh filename="./lsa1.1_new//meshes/urdf/obj_combined_hulls/left_pinkie_finger_dip_2_link.obj" />
</geometry>
</collision>
<inertial>
<origin xyz="-0.006998629676404673 -2.1496002602482204e-05 2.8862154115830973e-05" rpy="0 0 0" />
<mass value="0.005736094286194947" />
<inertia ixx="1.394445784719424e-07" ixy="8.011847885359641e-09" ixz="2.042628289687452e-10" iyy="2.4294468743419855e-07" iyz="-9.319543682461417e-11" izz="1.7936787803220335e-07" />
</inertial>
</link>

<joint name="left_pinkie_finger_dip_2" type="continuous">
<origin xyz="-0.004999999999999949 0.0 0.0" rpy="1.4589305181675693e-27 9.711686698029658e-27 2.5964396935292e-30" />
<parent link="left_pinkie_finger_dip_link" />
<child link="left_pinkie_finger_dip_2_link" />
<axis xyz="-9.711686698029657e-27 -1.469319057633645e-27 1.0" />
<mimic joint="left_pinkie_finger_dip" multiplier="1.0" offset="0" />
<limit effort="30" velocity="30" />

</joint>

<link name="left_pinkie_finger_tracker_link" />

<joint name="left_pinkie_finger_tracker" type="fixed">
<origin xyz="-0.01575000000000426 0.001192516402785576 -5.253087985571413e-15" rpy="1.5707963267948986 9.318143328023503e-16 -3.141592653589786" />
<parent link="left_pinkie_finger_dip_2_link" />
<child link="left_pinkie_finger_tracker_link" />
</joint>

<link name="left_index_finger_dip_2_link">
<visual>
<origin xyz="0.07049999999999998 0.0 0.0" rpy="-1.5707963267948966 -1.5707963267948966 0.0" />
<geometry>
<mesh filename="./lsa1.1_new//meshes/urdf/obj_combined_hulls/left_index_finger_dip_2_link.obj" />
</geometry>
</visual>
<collision>
<origin xyz="0.07049999999999998 0.0 0.0" rpy="-1.5707963267948966 -1.5707963267948966 0.0" />
<geometry>
<mesh filename="./lsa1.1_new//meshes/urdf/obj_combined_hulls/left_index_finger_dip_2_link.obj" />
</geometry>
</collision>
<inertial>
<origin xyz="-0.006998629676404934 -2.149600260250184e-05 2.886215411589962e-05" rpy="0 0 0" />
<mass value="0.005736094286194947" />
<inertia ixx="1.394445784719409e-07" ixy="8.011847885360313e-09" ixz="2.042628289695063e-10" iyy="2.4294468743419437e-07" iyz="-9.319543682360825e-11" izz="1.79367878032203e-07" />
</inertial>
</link>

<joint name="left_index_finger_dip_2" type="continuous">
<origin xyz="-0.0050000000000000044 -2.7755575615628914e-17 0.0" rpy="-5.003879913543157e-15 -1.6245699190072131e-15 -1.0897643917195043e-29" />
<parent link="left_index_finger_dip_link" />
<child link="left_index_finger_dip_2_link" />
<axis xyz="-1.6245699175116543e-15 5.0038799135431226e-15 1.000000000000019" />
<mimic joint="left_index_finger_dip" multiplier="1.0" offset="0" />
<limit effort="30" velocity="30" />

</joint>

<link name="left_index_finger_tracker_link" />

<joint name="left_index_finger_tracker" type="fixed">
<origin xyz="-0.015750000000005107 0.001192516402786633 -4.5173707941162156e-15" rpy="1.5707963267948983 7.810526325116006e-18 3.141592653589787" />
<parent link="left_index_finger_dip_2_link" />
<child link="left_index_finger_tracker_link" />
</joint>

<link name="left_ring_finger_dip_2_link">
<visual>
<origin xyz="0.07050000000000009 2.7755575615628914e-17 0.0" rpy="-1.5707963267948966 -1.5707963267948966 0.0" />
<geometry>
<mesh filename="./lsa1.1_new//meshes/urdf/obj_combined_hulls/left_ring_finger_dip_2_link.obj" />
</geometry>
</visual>
<collision>
<origin xyz="0.07050000000000009 2.7755575615628914e-17 0.0" rpy="-1.5707963267948966 -1.5707963267948966 0.0" />
<geometry>
<mesh filename="./lsa1.1_new//meshes/urdf/obj_combined_hulls/left_ring_finger_dip_2_link.obj" />
</geometry>
</collision>
<inertial>
<origin xyz="-0.006998629676404594 -2.1496002602568445e-05 2.8862154115885407e-05" rpy="0 0 0" />
<mass value="0.005736094286194946" />
<inertia ixx="1.3944457847194388e-07" ixy="8.011847885360038e-09" ixz="2.0426282896671402e-10" iyy="2.4294468743420146e-07" iyz="-9.319543682251815e-11" izz="1.7936787803220382e-07" />
</inertial>
</link>

<joint name="left_ring_finger_dip_2" type="continuous">
<origin xyz="-0.004999999999999949 0.0 6.938893903907228e-18" rpy="1.5170885145653109e-25 6.123234098460882e-17 -2.3365255970354835e-29" />
<parent link="left_ring_finger_dip_link" />
<child link="left_ring_finger_dip_2_link" />
<axis xyz="6.123234097489717e-17 -1.5171032628849218e-25 1.0000000000000004" />
<mimic joint="left_ring_finger_dip" multiplier="1.0" offset="0" />
<limit effort="30" velocity="30" />

</joint>

<link name="left_ring_finger_tracker_link" />

<joint name="left_ring_finger_tracker" type="fixed">
<origin xyz="-0.015750000000004177 0.0011925164027855653 -5.030206959210225e-15" rpy="1.5707963267948981 7.665868401314818e-16 -3.1415926535897856" />
<parent link="left_ring_finger_dip_2_link" />
<child link="left_ring_finger_tracker_link" />
</joint>

</robot>
